Workbook

Sheet Cover
B2: ISO37101 assessment
B4: If needed, see the "HowTo" tab for next actions
B6: Content | C6: Activities. | F6: Summary table: | G6: The following table summarizes the finding of this assessment.
B8: WP | C8: Across WP | F8: Average Score | G8: Attractiveness | I8: Environment | K8: Resilience | M8: Resources | O8: Cohesion | Q8: Well Being | T8: Reviewed | U8: Review | V8: Content | W8: Title
B9: LL | C9: Paris | G9: Bld. | H9: Neig. | I9: Bld. | J9: Neig. | K9: Bld. | L9: Neig. | M9: Bld. | N9: Neig. | O9: Bld. | P9: Neig. | Q9: Bld. | R9: Neig. | T9: N | U9: 9b2763acccbd | V9: Paris Budget | W9: Revamp parks for better usability.
B10: Date | C10: September 14, 2025 - 06:15PM | F10: =LEFT(Definitions!B12,25)&"…" | G10: =IFERROR(AVERAGE(9b2763acccbd!C39),"") | H10: =IFERROR(AVERAGE(9b2763acccbd!D39),"") | I10: =IFERROR(AVERAGE(9b2763acccbd!E39),"") | J10: =IFERROR(AVERAGE(9b2763acccbd!F39),"") | K10: =IFERROR(AVERAGE(9b2763acccbd!G39),"") | L10: =IFERROR(AVERAGE(9b2763acccbd!H39),"") | M10: =IFERROR(AVERAGE(9b2763acccbd!I39),"") | N10: =IFERROR(AVERAGE(9b2763acccbd!J39),"") | ... R10: =IFERROR(AVERAGE(9b2763acccbd!N39),"")
F11: =LEFT(Definitions!B13,25)&"…" | G11: =IFERROR(AVERAGE(9b2763acccbd!C40),"") | H11: =IFERROR(AVERAGE(9b2763acccbd!D40),"") | I11: =IFERROR(AVERAGE(9b2763acccbd!E40),"") | J11: =IFERROR(AVERAGE(9b2763acccbd!F40),"") | K11: =IFERROR(AVERAGE(9b2763acccbd!G40),"") | L11: =IFERROR(AVERAGE(9b2763acccbd!H40),"") | M11: =IFERROR(AVERAGE(9b2763acccbd!I40),"") | N11: =IFERROR(AVERAGE(9b2763acccbd!J40),"") | ... R11: =IFERROR(AVERAGE(9b2763acccbd!N40),"")
B12: Author(s) | C12: Automated | F12: =LEFT(Definitions!B14,25)&"…" | G12: =IFERROR(AVERAGE(9b2763acccbd!C41),"") | H12: =IFERROR(AVERAGE(9b2763acccbd!D41),"") | I12: =IFERROR(AVERAGE(9b2763acccbd!E41),"") | J12: =IFERROR(AVERAGE(9b2763acccbd!F41),"") | K12: =IFERROR(AVERAGE(9b2763acccbd!G41),"") | L12: =IFERROR(AVERAGE(9b2763acccbd!H41),"") | M12: =IFERROR(AVERAGE(9b2763acccbd!I41),"") | N12: =IFERROR(AVERAGE(9b2763acccbd!J41),"") | ... R12: =IFERROR(AVERAGE(9b2763acccbd!N41),"")
F13: =LEFT(Definitions!B15,25)&"…" | G13: =IFERROR(AVERAGE(9b2763acccbd!C42),"") | H13: =IFERROR(AVERAGE(9b2763acccbd!D42),"") | I13: =IFERROR(AVERAGE(9b2763acccbd!E42),"") | J13: =IFERROR(AVERAGE(9b2763acccbd!F42),"") | K13: =IFERROR(AVERAGE(9b2763acccbd!G42),"") | L13: =IFERROR(AVERAGE(9b2763acccbd!H42),"") | M13: =IFERROR(AVERAGE(9b2763acccbd!I42),"") | N13: =IFERROR(AVERAGE(9b2763acccbd!J42),"") | ... R13: =IFERROR(AVERAGE(9b2763acccbd!N42),"")
F14: =LEFT(Definitions!B16,25)&"…" | G14: =IFERROR(AVERAGE(9b2763acccbd!C43),"") | H14: =IFERROR(AVERAGE(9b2763acccbd!D43),"") | I14: =IFERROR(AVERAGE(9b2763acccbd!E43),"") | J14: =IFERROR(AVERAGE(9b2763acccbd!F43),"") | K14: =IFERROR(AVERAGE(9b2763acccbd!G43),"") | L14: =IFERROR(AVERAGE(9b2763acccbd!H43),"") | M14: =IFERROR(AVERAGE(9b2763acccbd!I43),"") | N14: =IFERROR(AVERAGE(9b2763acccbd!J43),"") | ... R14: =IFERROR(AVERAGE(9b2763acccbd!N43),"")
F15: =LEFT(Definitions!B17,25)&"…" | G15: =IFERROR(AVERAGE(9b2763acccbd!C44),"") | H15: =IFERROR(AVERAGE(9b2763acccbd!D44),"") | I15: =IFERROR(AVERAGE(9b2763acccbd!E44),"") | J15: =IFERROR(AVERAGE(9b2763acccbd!F44),"") | K15: =IFERROR(AVERAGE(9b2763acccbd!G44),"") | L15: =IFERROR(AVERAGE(9b2763acccbd!H44),"") | M15: =IFERROR(AVERAGE(9b2763acccbd!I44),"") | N15: =IFERROR(AVERAGE(9b2763acccbd!J44),"") | ... R15: =IFERROR(AVERAGE(9b2763acccbd!N44),"")
B16: Checked | F16: =LEFT(Definitions!B18,25)&"…" | G16: =IFERROR(AVERAGE(9b2763acccbd!C45),"") | H16: =IFERROR(AVERAGE(9b2763acccbd!D45),"") | I16: =IFERROR(AVERAGE(9b2763acccbd!E45),"") | J16: =IFERROR(AVERAGE(9b2763acccbd!F45),"") | K16: =IFERROR(AVERAGE(9b2763acccbd!G45),"") | L16: =IFERROR(AVERAGE(9b2763acccbd!H45),"") | M16: =IFERROR(AVERAGE(9b2763acccbd!I45),"") | N16: =IFERROR(AVERAGE(9b2763acccbd!J45),"") | ... R16: =IFERROR(AVERAGE(9b2763acccbd!N45),"")
F17: =LEFT(Definitions!B19,25)&"…" | G17: =IFERROR(AVERAGE(9b2763acccbd!C46),"") | H17: =IFERROR(AVERAGE(9b2763acccbd!D46),"") | I17: =IFERROR(AVERAGE(9b2763acccbd!E46),"") | J17: =IFERROR(AVERAGE(9b2763acccbd!F46),"") | K17: =IFERROR(AVERAGE(9b2763acccbd!G46),"") | L17: =IFERROR(AVERAGE(9b2763acccbd!H46),"") | M17: =IFERROR(AVERAGE(9b2763acccbd!I46),"") | N17: =IFERROR(AVERAGE(9b2763acccbd!J46),"") | ... R17: =IFERROR(AVERAGE(9b2763acccbd!N46),"")
F18: =LEFT(Definitions!B20,25)&"…" | G18: =IFERROR(AVERAGE(9b2763acccbd!C47),"") | H18: =IFERROR(AVERAGE(9b2763acccbd!D47),"") | I18: =IFERROR(AVERAGE(9b2763acccbd!E47),"") | J18: =IFERROR(AVERAGE(9b2763acccbd!F47),"") | K18: =IFERROR(AVERAGE(9b2763acccbd!G47),"") | L18: =IFERROR(AVERAGE(9b2763acccbd!H47),"") | M18: =IFERROR(AVERAGE(9b2763acccbd!I47),"") | N18: =IFERROR(AVERAGE(9b2763acccbd!J47),"") | ... R18: =IFERROR(AVERAGE(9b2763acccbd!N47),"")
F19: =LEFT(Definitions!B21,25)&"…" | G19: =IFERROR(AVERAGE(9b2763acccbd!C48),"") | H19: =IFERROR(AVERAGE(9b2763acccbd!D48),"") | I19: =IFERROR(AVERAGE(9b2763acccbd!E48),"") | J19: =IFERROR(AVERAGE(9b2763acccbd!F48),"") | K19: =IFERROR(AVERAGE(9b2763acccbd!G48),"") | L19: =IFERROR(AVERAGE(9b2763acccbd!H48),"") | M19: =IFERROR(AVERAGE(9b2763acccbd!I48),"") | N19: =IFERROR(AVERAGE(9b2763acccbd!J48),"") | ... R19: =IFERROR(AVERAGE(9b2763acccbd!N48),"")
B20: Validated | F20: =LEFT(Definitions!B22,25)&"…" | G20: =IFERROR(AVERAGE(9b2763acccbd!C49),"") | H20: =IFERROR(AVERAGE(9b2763acccbd!D49),"") | I20: =IFERROR(AVERAGE(9b2763acccbd!E49),"") | J20: =IFERROR(AVERAGE(9b2763acccbd!F49),"") | K20: =IFERROR(AVERAGE(9b2763acccbd!G49),"") | L20: =IFERROR(AVERAGE(9b2763acccbd!H49),"") | M20: =IFERROR(AVERAGE(9b2763acccbd!I49),"") | N20: =IFERROR(AVERAGE(9b2763acccbd!J49),"") | ... R20: =IFERROR(AVERAGE(9b2763acccbd!N49),"")
F21: =LEFT(Definitions!B23,25)&"…" | G21: =IFERROR(AVERAGE(9b2763acccbd!C50),"") | H21: =IFERROR(AVERAGE(9b2763acccbd!D50),"") | I21: =IFERROR(AVERAGE(9b2763acccbd!E50),"") | J21: =IFERROR(AVERAGE(9b2763acccbd!F50),"") | K21: =IFERROR(AVERAGE(9b2763acccbd!G50),"") | L21: =IFERROR(AVERAGE(9b2763acccbd!H50),"") | M21: =IFERROR(AVERAGE(9b2763acccbd!I50),"") | N21: =IFERROR(AVERAGE(9b2763acccbd!J50),"") | ... R21: =IFERROR(AVERAGE(9b2763acccbd!N50),"")
B24: Version of tool | C24: (15/11/2024) | F24: Number of count | G24: Attractiveness | I24: Environment | K24: Resilience | M24: Resources | O24: Cohesion | Q24: Well Being
G25: Bld. | H25: Neig. | I25: Bld. | J25: Neig. | K25: Bld. | L25: Neig. | M25: Bld. | N25: Neig. | O25: Bld. | P25: Neig. | Q25: Bld. | R25: Neig.
F26: =F10 | G26: =IF(ISNUMBER(9b2763acccbd!C39),ISNUMBER(9b2763acccbd!C39),"") | H26: =IF(ISNUMBER(9b2763acccbd!D39),ISNUMBER(9b2763acccbd!D39),"") | I26: =IF(ISNUMBER(9b2763acccbd!E39),ISNUMBER(9b2763acccbd!E39),"") | J26: =IF(ISNUMBER(9b2763acccbd!F39),ISNUMBER(9b2763acccbd!F39),"") | K26: =IF(ISNUMBER(9b2763acccbd!G39),ISNUMBER(9b2763acccbd!G39),"") | L26: =IF(ISNUMBER(9b2763acccbd!H39),ISNUMBER(9b2763acccbd!H39),"") | M26: =IF(ISNUMBER(9b2763acccbd!I39),ISNUMBER(9b2763acccbd!I39),"") | N26: =IF(ISNUMBER(9b2763acccbd!J39),ISNUMBER(9b2763acccbd!J39),"") | ... R26: =IF(ISNUMBER(9b2763acccbd!N39),ISNUMBER(9b2763acccbd!N39),"")
F27: =F11 | G27: =IF(ISNUMBER(9b2763acccbd!C40),ISNUMBER(9b2763acccbd!C40),"") | H27: =IF(ISNUMBER(9b2763acccbd!D40),ISNUMBER(9b2763acccbd!D40),"") | I27: =IF(ISNUMBER(9b2763acccbd!E40),ISNUMBER(9b2763acccbd!E40),"") | J27: =IF(ISNUMBER(9b2763acccbd!F40),ISNUMBER(9b2763acccbd!F40),"") | K27: =IF(ISNUMBER(9b2763acccbd!G40),ISNUMBER(9b2763acccbd!G40),"") | L27: =IF(ISNUMBER(9b2763acccbd!H40),ISNUMBER(9b2763acccbd!H40),"") | M27: =IF(ISNUMBER(9b2763acccbd!I40),ISNUMBER(9b2763acccbd!I40),"") | N27: =IF(ISNUMBER(9b2763acccbd!J40),ISNUMBER(9b2763acccbd!J40),"") | ... R27: =IF(ISNUMBER(9b2763acccbd!N40),ISNUMBER(9b2763acccbd!N40),"")
F28: =F12 | G28: =IF(ISNUMBER(9b2763acccbd!C41),ISNUMBER(9b2763acccbd!C41),"") | H28: =IF(ISNUMBER(9b2763acccbd!D41),ISNUMBER(9b2763acccbd!D41),"") | I28: =IF(ISNUMBER(9b2763acccbd!E41),ISNUMBER(9b2763acccbd!E41),"") | J28: =IF(ISNUMBER(9b2763acccbd!F41),ISNUMBER(9b2763acccbd!F41),"") | K28: =IF(ISNUMBER(9b2763acccbd!G41),ISNUMBER(9b2763acccbd!G41),"") | L28: =IF(ISNUMBER(9b2763acccbd!H41),ISNUMBER(9b2763acccbd!H41),"") | M28: =IF(ISNUMBER(9b2763acccbd!I41),ISNUMBER(9b2763acccbd!I41),"") | N28: =IF(ISNUMBER(9b2763acccbd!J41),ISNUMBER(9b2763acccbd!J41),"") | ... R28: =IF(ISNUMBER(9b2763acccbd!N41),ISNUMBER(9b2763acccbd!N41),"")
F29: =F13 | G29: =IF(ISNUMBER(9b2763acccbd!C42),ISNUMBER(9b2763acccbd!C42),"") | H29: =IF(ISNUMBER(9b2763acccbd!D42),ISNUMBER(9b2763acccbd!D42),"") | I29: =IF(ISNUMBER(9b2763acccbd!E42),ISNUMBER(9b2763acccbd!E42),"") | J29: =IF(ISNUMBER(9b2763acccbd!F42),ISNUMBER(9b2763acccbd!F42),"") | K29: =IF(ISNUMBER(9b2763acccbd!G42),ISNUMBER(9b2763acccbd!G42),"") | L29: =IF(ISNUMBER(9b2763acccbd!H42),ISNUMBER(9b2763acccbd!H42),"") | M29: =IF(ISNUMBER(9b2763acccbd!I42),ISNUMBER(9b2763acccbd!I42),"") | N29: =IF(ISNUMBER(9b2763acccbd!J42),ISNUMBER(9b2763acccbd!J42),"") | ... R29: =IF(ISNUMBER(9b2763acccbd!N42),ISNUMBER(9b2763acccbd!N42),"")
F30: =F14 | G30: =IF(ISNUMBER(9b2763acccbd!C43),ISNUMBER(9b2763acccbd!C43),"") | H30: =IF(ISNUMBER(9b2763acccbd!D43),ISNUMBER(9b2763acccbd!D43),"") | I30: =IF(ISNUMBER(9b2763acccbd!E43),ISNUMBER(9b2763acccbd!E43),"") | J30: =IF(ISNUMBER(9b2763acccbd!F43),ISNUMBER(9b2763acccbd!F43),"") | K30: =IF(ISNUMBER(9b2763acccbd!G43),ISNUMBER(9b2763acccbd!G43),"") | L30: =IF(ISNUMBER(9b2763acccbd!H43),ISNUMBER(9b2763acccbd!H43),"") | M30: =IF(ISNUMBER(9b2763acccbd!I43),ISNUMBER(9b2763acccbd!I43),"") | N30: =IF(ISNUMBER(9b2763acccbd!J43),ISNUMBER(9b2763acccbd!J43),"") | ... R30: =IF(ISNUMBER(9b2763acccbd!N43),ISNUMBER(9b2763acccbd!N43),"")
F31: =F15 | G31: =IF(ISNUMBER(9b2763acccbd!C44),ISNUMBER(9b2763acccbd!C44),"") | H31: =IF(ISNUMBER(9b2763acccbd!D44),ISNUMBER(9b2763acccbd!D44),"") | I31: =IF(ISNUMBER(9b2763acccbd!E44),ISNUMBER(9b2763acccbd!E44),"") | J31: =IF(ISNUMBER(9b2763acccbd!F44),ISNUMBER(9b2763acccbd!F44),"") | K31: =IF(ISNUMBER(9b2763acccbd!G44),ISNUMBER(9b2763acccbd!G44),"") | L31: =IF(ISNUMBER(9b2763acccbd!H44),ISNUMBER(9b2763acccbd!H44),"") | M31: =IF(ISNUMBER(9b2763acccbd!I44),ISNUMBER(9b2763acccbd!I44),"") | N31: =IF(ISNUMBER(9b2763acccbd!J44),ISNUMBER(9b2763acccbd!J44),"") | ... R31: =IF(ISNUMBER(9b2763acccbd!N44),ISNUMBER(9b2763acccbd!N44),"")
F32: =F16 | G32: =IF(ISNUMBER(9b2763acccbd!C45),ISNUMBER(9b2763acccbd!C45),"") | H32: =IF(ISNUMBER(9b2763acccbd!D45),ISNUMBER(9b2763acccbd!D45),"") | I32: =IF(ISNUMBER(9b2763acccbd!E45),ISNUMBER(9b2763acccbd!E45),"") | J32: =IF(ISNUMBER(9b2763acccbd!F45),ISNUMBER(9b2763acccbd!F45),"") | K32: =IF(ISNUMBER(9b2763acccbd!G45),ISNUMBER(9b2763acccbd!G45),"") | L32: =IF(ISNUMBER(9b2763acccbd!H45),ISNUMBER(9b2763acccbd!H45),"") | M32: =IF(ISNUMBER(9b2763acccbd!I45),ISNUMBER(9b2763acccbd!I45),"") | N32: =IF(ISNUMBER(9b2763acccbd!J45),ISNUMBER(9b2763acccbd!J45),"") | ... R32: =IF(ISNUMBER(9b2763acccbd!N45),ISNUMBER(9b2763acccbd!N45),"")
F33: =F17 | G33: =IF(ISNUMBER(9b2763acccbd!C46),ISNUMBER(9b2763acccbd!C46),"") | H33: =IF(ISNUMBER(9b2763acccbd!D46),ISNUMBER(9b2763acccbd!D46),"") | I33: =IF(ISNUMBER(9b2763acccbd!E46),ISNUMBER(9b2763acccbd!E46),"") | J33: =IF(ISNUMBER(9b2763acccbd!F46),ISNUMBER(9b2763acccbd!F46),"") | K33: =IF(ISNUMBER(9b2763acccbd!G46),ISNUMBER(9b2763acccbd!G46),"") | L33: =IF(ISNUMBER(9b2763acccbd!H46),ISNUMBER(9b2763acccbd!H46),"") | M33: =IF(ISNUMBER(9b2763acccbd!I46),ISNUMBER(9b2763acccbd!I46),"") | N33: =IF(ISNUMBER(9b2763acccbd!J46),ISNUMBER(9b2763acccbd!J46),"") | ... R33: =IF(ISNUMBER(9b2763acccbd!N46),ISNUMBER(9b2763acccbd!N46),"")
F34: =F18 | G34: =IF(ISNUMBER(9b2763acccbd!C47),ISNUMBER(9b2763acccbd!C47),"") | H34: =IF(ISNUMBER(9b2763acccbd!D47),ISNUMBER(9b2763acccbd!D47),"") | I34: =IF(ISNUMBER(9b2763acccbd!E47),ISNUMBER(9b2763acccbd!E47),"") | J34: =IF(ISNUMBER(9b2763acccbd!F47),ISNUMBER(9b2763acccbd!F47),"") | K34: =IF(ISNUMBER(9b2763acccbd!G47),ISNUMBER(9b2763acccbd!G47),"") | L34: =IF(ISNUMBER(9b2763acccbd!H47),ISNUMBER(9b2763acccbd!H47),"") | M34: =IF(ISNUMBER(9b2763acccbd!I47),ISNUMBER(9b2763acccbd!I47),"") | N34: =IF(ISNUMBER(9b2763acccbd!J47),ISNUMBER(9b2763acccbd!J47),"") | ... R34: =IF(ISNUMBER(9b2763acccbd!N47),ISNUMBER(9b2763acccbd!N47),"")
F35: =F19 | G35: =IF(ISNUMBER(9b2763acccbd!C48),ISNUMBER(9b2763acccbd!C48),"") | H35: =IF(ISNUMBER(9b2763acccbd!D48),ISNUMBER(9b2763acccbd!D48),"") | I35: =IF(ISNUMBER(9b2763acccbd!E48),ISNUMBER(9b2763acccbd!E48),"") | J35: =IF(ISNUMBER(9b2763acccbd!F48),ISNUMBER(9b2763acccbd!F48),"") | K35: =IF(ISNUMBER(9b2763acccbd!G48),ISNUMBER(9b2763acccbd!G48),"") | L35: =IF(ISNUMBER(9b2763acccbd!H48),ISNUMBER(9b2763acccbd!H48),"") | M35: =IF(ISNUMBER(9b2763acccbd!I48),ISNUMBER(9b2763acccbd!I48),"") | N35: =IF(ISNUMBER(9b2763acccbd!J48),ISNUMBER(9b2763acccbd!J48),"") | ... R35: =IF(ISNUMBER(9b2763acccbd!N48),ISNUMBER(9b2763acccbd!N48),"")
F36: =F20 | G36: =IF(ISNUMBER(9b2763acccbd!C49),ISNUMBER(9b2763acccbd!C49),"") | H36: =IF(ISNUMBER(9b2763acccbd!D49),ISNUMBER(9b2763acccbd!D49),"") | I36: =IF(ISNUMBER(9b2763acccbd!E49),ISNUMBER(9b2763acccbd!E49),"") | J36: =IF(ISNUMBER(9b2763acccbd!F49),ISNUMBER(9b2763acccbd!F49),"") | K36: =IF(ISNUMBER(9b2763acccbd!G49),ISNUMBER(9b2763acccbd!G49),"") | L36: =IF(ISNUMBER(9b2763acccbd!H49),ISNUMBER(9b2763acccbd!H49),"") | M36: =IF(ISNUMBER(9b2763acccbd!I49),ISNUMBER(9b2763acccbd!I49),"") | N36: =IF(ISNUMBER(9b2763acccbd!J49),ISNUMBER(9b2763acccbd!J49),"") | ... R36: =IF(ISNUMBER(9b2763acccbd!N49),ISNUMBER(9b2763acccbd!N49),"")
F37: =F21 | G37: =IF(ISNUMBER(9b2763acccbd!C50),ISNUMBER(9b2763acccbd!C50),"") | H37: =IF(ISNUMBER(9b2763acccbd!D50),ISNUMBER(9b2763acccbd!D50),"") | I37: =IF(ISNUMBER(9b2763acccbd!E50),ISNUMBER(9b2763acccbd!E50),"") | J37: =IF(ISNUMBER(9b2763acccbd!F50),ISNUMBER(9b2763acccbd!F50),"") | K37: =IF(ISNUMBER(9b2763acccbd!G50),ISNUMBER(9b2763acccbd!G50),"") | L37: =IF(ISNUMBER(9b2763acccbd!H50),ISNUMBER(9b2763acccbd!H50),"") | M37: =IF(ISNUMBER(9b2763acccbd!I50),ISNUMBER(9b2763acccbd!I50),"") | N37: =IF(ISNUMBER(9b2763acccbd!J50),ISNUMBER(9b2763acccbd!J50),"") | ... R37: =IF(ISNUMBER(9b2763acccbd!N50),ISNUMBER(9b2763acccbd!N50),"")

Sheet HowTo
C1: How to use
B3: Step | C3: Description
B4: Step 1 | C4: Author/user sends their text for review (use cases, visions, ….)
B5: Step 2 | C5: LJ processes the text and..
B6: Step3 | C6: A draft assessment is created, in an excel format, and sent back o the author
C7: The authors checks green tabs, and can edit cells in yellow such as this cell. Other cells should not be edited.
B8: Step 4 | C8: Author sends back edited excel.
B9: Step 5 | C9: LJ updates the data and generates the assessment report.
B10: Step 6 | C10: Author receives an updated assessment
B12: Tabs | C12: Content
B13: Green tabs | C13: Contains assessments
B14: Blue tab | C14: Contains definition
B15: Black tab | C15: Cover hsset
B16: Orange tab | C16: How to and explanations

Sheet Definitions
A1: Definitions
B2: As per https://www.iso.org/obp/ui/en/#iso:std:iso:37104:ed-1:v1:en
A3: Purpose of sustainability
B4: Attractiveness | C4: represents a territory's capacity to draw and retain citizens, businesses, and other stakeholders through its appeal and dynamism. It encompasses economic vitality, cultural richness, sense of place and identity, quality of life features, and strategic connectivity. For green building neighborhoods specifically, attractiveness manifests through innovative sustainable architecture, integrated urban planning, cultural amenities, and infrastructure that enhances both livability and economic opportunities. The purpose focuses on creating spaces that are not just environmentally responsible but also economically vibrant and socially desirable.
B5: Preservation and improvement of environment | C5: focuses on enhancing environmental performance through specific measurable actions like reducing greenhouse gas emissions, protecting and restoring biodiversity and ecosystem services, and reducing health hazards. For GBNs, this translates into active environmental stewardship through building design, land use practices, and infrastructure that not only minimizes negative environmental impacts but actively contributes to ecological regeneration. This includes protecting ecosystems, managing plant and animal diversity, preserving migration corridors, and maintaining genetic diversity within urban contexts.
B6: Resilience | C6: refers to a community's adaptive capacity in complex and changing environments. For GBNs, this encompasses anticipating and adapting to climate change impacts, preparing for economic shocks and stresses, and developing social evolution strategies. The standard particularly emphasizes taking both short-term and long-term perspectives on planning, with key focuses on: Climate change mitigation and adaptation capabilities, Economic and social shock preparedness, Organizational crisis response and recovery, Ability to maintain essential functions during disruption, and Capacity to "degrade gracefully" when necessary. It emphasizes the importance of both physical infrastructure resilience and social resilience in creating sustainable communities.
B7: Responsible resource use | C7: focuses on sustainable consumption, distribution, and management of all resource types - natural, human, and financial. This purpose emphasizes: Improving land management practices, Reducing, reusing and recycling materials, Respecting resource scarcity (especially water and energy), Promoting sustainable production, storage and transport methods, a,d Implementing efficient waste management and circular economy principles. In the context of GBNs, this translates to smart resource management in building design and operations, efficient infrastructure systems, and the development of closed-loop resource cycles within neighborhoods. The standard highlights that responsible resource use requires considering both immediate consumption patterns and long-term resource availability.
B8: Social cohesion | C8: focuses on creating equitable access to services, fostering dialogue across community boundaries, and supporting diversity and inclusion. For GBNs, this means developing neighborhoods that promote social integration, preserve cultural heritage, strengthen community identity, and reduce inequalities. The standard emphasizes accessibility, cultural dialogue, and the creation of shared experiences that build a sense of belonging and enhance social mobility. This purpose recognizes that sustainable communities require strong social bonds and mutual understanding across different demographic groups, combining both physical design elements and social programs that encourage interaction and solidarity among residents.
B9: Well-being | C9: encompasses access to opportunities for quality of life enhancement, including education and professional training, a healthy environment, and improved living conditions. For GBNs, this translates into creating spaces that promote physical and mental health, safety, and community confidence. The standard highlights that well-being depends on tangible factors like environmental quality and access to services, as well as intangible elements like trust-building and collective maturity. This purpose recognizes that sustainable communities must actively contribute to residents' happiness, health, and overall life satisfaction through thoughtful design and service provision.
A11: Sustainability issue
B12: Governance, empowerment and engagement | C12: defined as a systemic approach to engaging all interested parties in community decision-making and development. The standard emphasizes that governance models need to foster systematic stakeholder involvement at every level, from policy-making to project implementation. For GBNs, this means creating transparent structures that encourage participation, facilitate community input, and ensure accountability in the development and management of sustainable neighborhoods. The standard highlights this issue as fundamental to successful sustainable development, requiring clear roles, responsibilities, and mechanisms for inclusive decision-making.
B13: Education and capacity building | C13: is defined as an issue that focuses on raising awareness, knowledge and skills at all levels to contribute to sustainable development, smartness and resilience. The standard emphasizes that education and capacity building should help develop competencies across the community that enable better understanding and implementation of sustainability practices. For GBNs, this translates into developing training programs, knowledge sharing platforms, and skill development initiatives that strengthen the community's ability to implement and maintain sustainable practices in the built environment.
B14: Innovation, creativity and research | C14: focuses on developing new forms of cooperation and cutting-edge designs while balancing risk management and ethical considerations. For GBNs, this issue promotes innovative solutions through research and creative problem-solving, encouraging new approaches to sustainable development while ensuring proper consideration of outcomes and implications. The standard positions this as a key driver for developing novel solutions to community challenges while maintaining responsible implementation practices.
B15: Health and care in the community | C15: defined as a crucial element that maintains and improves both physical and mental health within the community, contributing to its well-being and resilience. The standard emphasizes the importance of healthcare accessibility, preventive practices, and the relationship between environmental quality and community health. For GBNs, this translates into designing spaces and services that promote healthy living, ensure equitable access to healthcare, and create environments that support both physical and mental wellness.
B16: Culture and community identity | C16: defined as preserving lifestyles, including intangible elements like practices, know-how, languages, spirituality, and customs, while allowing for the evolution of heritage and traditions. For GBNs, this means creating spaces that respect and enhance local cultural identity while remaining open to cultural development and change. The standard emphasizes that this issue is crucial for maintaining community distinctiveness while embracing sustainable development.
B17: Living together, interdependence and mutuality | C17: focuses on developing collective and collaborative lifestyles that produce mutual economic and social benefits. The standard emphasizes this issue's role in fostering inter-generational equity and social mobility through shared experiences and responsibilities. For GBNs, this translates into creating spaces and systems that encourage interaction, cooperation, and mutual support among community members while promoting inclusive social and economic development.
B18: Economy and sustainable production and consumption | C18: encompasses support for local production, consumption and exchange, promoting economic diversity, employment and employability. The standard emphasizes resource efficiency, life cycle approaches, and transparency as key factors. For GBNs, this means creating economic systems that support sustainable local businesses, encourage responsible consumption patterns, and provide diverse employment opportunities while considering environmental impacts throughout the production and consumption cycle.
B19: Living and working environment | C19: focuses on facilitating fair and equitable access to quality living and working conditions that meet stakeholder needs and expectations. For GBNs, this means creating spaces that balance environmental sustainability with quality of life, addressing issues like housing quality, workplace conditions, and access to amenities. The standard emphasizes this issue's importance in creating sustainable communities that support both residential well-being and economic activity.
B20: Safety and security | C20: addresses ensuring communities are considered safe, both internally by members and externally by outsiders. This includes enforcing the right to privacy, protecting public security, and preventing and managing risks within the community. Key aspects involve taking safety and security into account when planning land use, improving safety and preventing crime and violence for all, and enhancing the safety and welcoming nature of public spaces through policies. Assessing initiatives against this issue helps stakeholders understand how they are addressing safety, security and risk management for sustainable urban development.
B21: Biodiversity and ecosystem services | C21: focuses on the preservation and improvement of the local, regional and global environment, especially the protection, restoration and enhancement of biological diversity and ecosystem services. This includes maintaining the diversity of fauna, flora and genetic resources. Preserving biodiversity and ecosystem services is crucial to ensure safe and pleasant living conditions, and enhances the attractiveness of communities while strengthening their economic development. Key aspects involve assessing the loss of biodiversity and responding to related risks, as well as ensuring biodiversity and ecosystem services are considered major natural resources to be managed sustainably.
B22: Community smart infrastructures | C22: ensuring high-quality utilities and services that support sustainable community development. This includes urban water supply and wastewater treatment, waste collection and processing, energy production and distribution, and integration of digital communication networks.
B23: Mobility | C23: defined as the provision of safe, comfortable, comprehensive, dependable, efficient, accessible, affordable and appropriate mobility services for different age and special needs groups, particularly for persons with disabilities. This includes maintaining a reliable transport system, improving connectivity, encouraging non-motorized traffic like walking and cycling, and facilitating the transport of goods.

Sheet 9b2763acccbd
B2: Self assessment sheet
B4: Activity | C4: Review of Paris Budget
B5: Title | C5: Revamp parks for better usability. | J5: ID: | L5: 9b2763acccbd
B6: Deliverable | C6: Paris Budget | J6: LL: | L6: Paris
B7: Reviewed by | J7: Date of review:
B8: Review | C8: 1/ Constat Il s’agit de repenser globalement le square Raoul Nordling et le jardin Louis Majorelle, pour qu’ils répondent mieux à leurs usages : - Le square Raoul Nordling (1 255 m²), est très utilisé par les familles. L'aire de jeux pour enfants est surchargée. - Le jardin Louis Majorelle (2 700 m²), bien que deux fois plus grand est beaucoup moins fréquenté en raison des massifs compacts et d’entrées peu visibles depuis l’espace public et de sa non mise en valeur. 2/ Propositions - Créer une 3ème aire de jeux pour enfants dans le square Raoul Nordling. - Réaménager le jardin Louis Majorelle pour l’aérer et valoriser ses plantations. 3/ Conclusion Ce projet déposé par le Conseil de Quartier Bastille-Popincourt vise à redonner de la convivialité et à embellir cet espace de plus de 4 000 m2 au pied de l'Eglise Ste-Marguerite. Où en est ce projet ? Jeudi 12 septembre 2019 La mairie du 11e a organisé deux réunions de concertation pour la définition du programme au printemps 2019. Les études sont en cours de réalisation
B10: ID | C10: Purp. | D10: Act. | E10: Bld. | F10: Neig. | G10: Justification
C11: A1 | D11: B8 | F11: 5 | G11: The proposal aims to enhance the usability and appeal of the square Raoul Nordling and the garden Louis Majorelle by adding a new playground and improving the existing garden. This will create a more vibrant and appealing community space, thus attracting more families and visitors. The emphasis on improving the size, visibility, and aesthetic quality of these spaces contributes significantly to the overall quality of life in the neighborhood.
C12: A2 | D12: B10 | F12: 4 | G12: The plan includes the intention to aerate and valorize the plantings in the Louis Majorelle garden, which can contribute to preserving biodiversity in urban settings. By enhancing the environment within these green spaces, it supports ecosystem services and promotes better environmental conditions for both flora and fauna.
C13: A5 | D13: B5 | F13: 4 | G13: The initiative aims to create convivial spaces that promote social interactions among community members, particularly families. By improving these public areas to be more welcoming and user-friendly, the project fosters a sense of belonging and community identity, essential for social cohesion.
C14: A6 | D14: B4 | F14: 5 | G14: By responding to the needs of families and enhancing play areas for children, the project directly contributes to the mental and physical well-being of the community. The improvements aim to create healthier outdoor environments where families can spend time together, positively impacting overall community health.
C15: A3 | D15: B6 | F15: 3 | G15: While not explicitly stated, improving community spaces contributes to building community resilience by encouraging interdependence and mutual support through communal areas for recreation and gathering, which can help reinforce social bonds in times of need.
C16: A1 | D16: B7 | F16: 3 | G16: The development of attractive community spaces can stimulate local economic activity by attracting visitors and supporting local businesses. Enhanced appeal through beautification allows for diverse opportunities for local commerce and engagement.
C17: A4 | D17: B11 | F17: 2 | G17: The project proposal may imply certain improvements in the infrastructure of the green spaces that can include better waste management and resource-efficient designs; however, specific strategies in this regard were not outlined.
C18: A2 | D18: B8 | F18: 3 | G18: By focusing on enhancing the garden and square, the project promotes a better living and working environment, encouraging people to utilize these spaces which better serve their needs and contribute positively to their lifestyle.
C19: A5 | D19: B1 | F19: 3 | G19: The involvement of the local council and the organization of public consultation meetings indicates a practice of governance that encourages community engagement in the decision-making process.
B22: Definitions | C22: A (Purposes) | I22: B (Actions)
C23: 1. Attractiveness | I23: 1. Governance, empowerment, and engagement
C24: 2. Preservation and improvement of the environment | I24: 2. Education and capacity building
C25: 3. Resilience | I25: 3. Innovation, creativity, and research
C26: 4. Responsible resource use | I26: 4. Health and care in the community
C27: 5. Social cohesion | I27: 5. Culture and community identity
C28: 6. Wellbeing | I28: 6. Living together, interdependence and mutuality
I29: 7. Economy and sustainable production and consumption
I30: 8. Living and working environment
I31: 9. Safety and security
I32: 10. Biodiversity and ecosystem services
I33: 11. Community smart infrastructures
I34: 12. Mobility
C37: A1 | E37: A2 | G37: A3 | I37: A4 | K37: A5 | M37: A6
C38: Bld. | D38: Neig. | E38: Bld. | F38: Neig. | G38: Bld. | H38: Neig. | I38: Bld. | J38: Neig. | K38: Bld. | L38: Neig. | M38: Bld. | N38: Neig.
B39: B1 | C39: =IFERROR(AVERAGEIFS($E$11:$E$20,$C$11:$C$20,C$37,$D$11:$D$20,$B39),"") | D39: =IFERROR(AVERAGEIFS($F$11:$F$20,$C$11:$C$20,C$37,$D$11:$D$20,$B39),"") | E39: =IFERROR(AVERAGEIFS($E$11:$E$20,$C$11:$C$20,E$37,$D$11:$D$20,$B39),"") | F39: =IFERROR(AVERAGEIFS($F$11:$F$20,$C$11:$C$20,E$37,$D$11:$D$20,$B39),"") | G39: =IFERROR(AVERAGEIFS($E$11:$E$20,$C$11:$C$20,G$37,$D$11:$D$20,$B39),"") | H39: =IFERROR(AVERAGEIFS($F$11:$F$20,$C$11:$C$20,G$37,$D$11:$D$20,$B39),"") | I39: =IFERROR(AVERAGEIFS($E$11:$E$20,$C$11:$C$20,I$37,$D$11:$D$20,$B39),"") | J39: =IFERROR(AVERAGEIFS($F$11:$F$20,$C$11:$C$20,I$37,$D$11:$D$20,$B39),"") | K39: =IFERROR(AVERAGEIFS($E$11:$E$20,$C$11:$C$20,K$37,$D$11:$D$20,$B39),"") | L39: =IFERROR(AVERAGEIFS($F$11:$F$20,$C$11:$C$20,K$37,$D$11:$D$20,$B39),"") | M39: =IFERROR(AVERAGEIFS($E$11:$E$20,$C$11:$C$20,M$37,$D$11:$D$20,$B39),"") | N39: =IFERROR(AVERAGEIFS($F$11:$F$20,$C$11:$C$20,M$37,$D$11:$D$20,$B39),"")
B40: B2 | C40: =IFERROR(AVERAGEIFS($E$11:$E$20,$C$11:$C$20,C$37,$D$11:$D$20,$B40),"") | D40: =IFERROR(AVERAGEIFS($F$11:$F$20,$C$11:$C$20,C$37,$D$11:$D$20,$B40),"") | E40: =IFERROR(AVERAGEIFS($E$11:$E$20,$C$11:$C$20,E$37,$D$11:$D$20,$B40),"") | F40: =IFERROR(AVERAGEIFS($F$11:$F$20,$C$11:$C$20,E$37,$D$11:$D$20,$B40),"") | G40: =IFERROR(AVERAGEIFS($E$11:$E$20,$C$11:$C$20,G$37,$D$11:$D$20,$B40),"") | H40: =IFERROR(AVERAGEIFS($F$11:$F$20,$C$11:$C$20,G$37,$D$11:$D$20,$B40),"") | I40: =IFERROR(AVERAGEIFS($E$11:$E$20,$C$11:$C$20,I$37,$D$11:$D$20,$B40),"") | J40: =IFERROR(AVERAGEIFS($F$11:$F$20,$C$11:$C$20,I$37,$D$11:$D$20,$B40),"") | K40: =IFERROR(AVERAGEIFS($E$11:$E$20,$C$11:$C$20,K$37,$D$11:$D$20,$B40),"") | L40: =IFERROR(AVERAGEIFS($F$11:$F$20,$C$11:$C$20,K$37,$D$11:$D$20,$B40),"") | M40: =IFERROR(AVERAGEIFS($E$11:$E$20,$C$11:$C$20,M$37,$D$11:$D$20,$B40),"") | N40: =IFERROR(AVERAGEIFS($F$11:$F$20,$C$11:$C$20,M$37,$D$11:$D$20,$B40),"")
B41: B3 | C41: =IFERROR(AVERAGEIFS($E$11:$E$20,$C$11:$C$20,C$37,$D$11:$D$20,$B41),"") | D41: =IFERROR(AVERAGEIFS($F$11:$F$20,$C$11:$C$20,C$37,$D$11:$D$20,$B41),"") | E41: =IFERROR(AVERAGEIFS($E$11:$E$20,$C$11:$C$20,E$37,$D$11:$D$20,$B41),"") | F41: =IFERROR(AVERAGEIFS($F$11:$F$20,$C$11:$C$20,E$37,$D$11:$D$20,$B41),"") | G41: =IFERROR(AVERAGEIFS($E$11:$E$20,$C$11:$C$20,G$37,$D$11:$D$20,$B41),"") | H41: =IFERROR(AVERAGEIFS($F$11:$F$20,$C$11:$C$20,G$37,$D$11:$D$20,$B41),"") | I41: =IFERROR(AVERAGEIFS($E$11:$E$20,$C$11:$C$20,I$37,$D$11:$D$20,$B41),"") | J41: =IFERROR(AVERAGEIFS($F$11:$F$20,$C$11:$C$20,I$37,$D$11:$D$20,$B41),"") | K41: =IFERROR(AVERAGEIFS($E$11:$E$20,$C$11:$C$20,K$37,$D$11:$D$20,$B41),"") | L41: =IFERROR(AVERAGEIFS($F$11:$F$20,$C$11:$C$20,K$37,$D$11:$D$20,$B41),"") | M41: =IFERROR(AVERAGEIFS($E$11:$E$20,$C$11:$C$20,M$37,$D$11:$D$20,$B41),"") | N41: =IFERROR(AVERAGEIFS($F$11:$F$20,$C$11:$C$20,M$37,$D$11:$D$20,$B41),"")
B42: B4 | C42: =IFERROR(AVERAGEIFS($E$11:$E$20,$C$11:$C$20,C$37,$D$11:$D$20,$B42),"") | D42: =IFERROR(AVERAGEIFS($F$11:$F$20,$C$11:$C$20,C$37,$D$11:$D$20,$B42),"") | E42: =IFERROR(AVERAGEIFS($E$11:$E$20,$C$11:$C$20,E$37,$D$11:$D$20,$B42),"") | F42: =IFERROR(AVERAGEIFS($F$11:$F$20,$C$11:$C$20,E$37,$D$11:$D$20,$B42),"") | G42: =IFERROR(AVERAGEIFS($E$11:$E$20,$C$11:$C$20,G$37,$D$11:$D$20,$B42),"") | H42: =IFERROR(AVERAGEIFS($F$11:$F$20,$C$11:$C$20,G$37,$D$11:$D$20,$B42),"") | I42: =IFERROR(AVERAGEIFS($E$11:$E$20,$C$11:$C$20,I$37,$D$11:$D$20,$B42),"") | J42: =IFERROR(AVERAGEIFS($F$11:$F$20,$C$11:$C$20,I$37,$D$11:$D$20,$B42),"") | K42: =IFERROR(AVERAGEIFS($E$11:$E$20,$C$11:$C$20,K$37,$D$11:$D$20,$B42),"") | L42: =IFERROR(AVERAGEIFS($F$11:$F$20,$C$11:$C$20,K$37,$D$11:$D$20,$B42),"") | M42: =IFERROR(AVERAGEIFS($E$11:$E$20,$C$11:$C$20,M$37,$D$11:$D$20,$B42),"") | N42: =IFERROR(AVERAGEIFS($F$11:$F$20,$C$11:$C$20,M$37,$D$11:$D$20,$B42),"")
B43: B5 | C43: =IFERROR(AVERAGEIFS($E$11:$E$20,$C$11:$C$20,C$37,$D$11:$D$20,$B43),"") | D43: =IFERROR(AVERAGEIFS($F$11:$F$20,$C$11:$C$20,C$37,$D$11:$D$20,$B43),"") | E43: =IFERROR(AVERAGEIFS($E$11:$E$20,$C$11:$C$20,E$37,$D$11:$D$20,$B43),"") | F43: =IFERROR(AVERAGEIFS($F$11:$F$20,$C$11:$C$20,E$37,$D$11:$D$20,$B43),"") | G43: =IFERROR(AVERAGEIFS($E$11:$E$20,$C$11:$C$20,G$37,$D$11:$D$20,$B43),"") | H43: =IFERROR(AVERAGEIFS($F$11:$F$20,$C$11:$C$20,G$37,$D$11:$D$20,$B43),"") | I43: =IFERROR(AVERAGEIFS($E$11:$E$20,$C$11:$C$20,I$37,$D$11:$D$20,$B43),"") | J43: =IFERROR(AVERAGEIFS($F$11:$F$20,$C$11:$C$20,I$37,$D$11:$D$20,$B43),"") | K43: =IFERROR(AVERAGEIFS($E$11:$E$20,$C$11:$C$20,K$37,$D$11:$D$20,$B43),"") | L43: =IFERROR(AVERAGEIFS($F$11:$F$20,$C$11:$C$20,K$37,$D$11:$D$20,$B43),"") | M43: =IFERROR(AVERAGEIFS($E$11:$E$20,$C$11:$C$20,M$37,$D$11:$D$20,$B43),"") | N43: =IFERROR(AVERAGEIFS($F$11:$F$20,$C$11:$C$20,M$37,$D$11:$D$20,$B43),"")
B44: B6 | C44: =IFERROR(AVERAGEIFS($E$11:$E$20,$C$11:$C$20,C$37,$D$11:$D$20,$B44),"") | D44: =IFERROR(AVERAGEIFS($F$11:$F$20,$C$11:$C$20,C$37,$D$11:$D$20,$B44),"") | E44: =IFERROR(AVERAGEIFS($E$11:$E$20,$C$11:$C$20,E$37,$D$11:$D$20,$B44),"") | F44: =IFERROR(AVERAGEIFS($F$11:$F$20,$C$11:$C$20,E$37,$D$11:$D$20,$B44),"") | G44: =IFERROR(AVERAGEIFS($E$11:$E$20,$C$11:$C$20,G$37,$D$11:$D$20,$B44),"") | H44: =IFERROR(AVERAGEIFS($F$11:$F$20,$C$11:$C$20,G$37,$D$11:$D$20,$B44),"") | I44: =IFERROR(AVERAGEIFS($E$11:$E$20,$C$11:$C$20,I$37,$D$11:$D$20,$B44),"") | J44: =IFERROR(AVERAGEIFS($F$11:$F$20,$C$11:$C$20,I$37,$D$11:$D$20,$B44),"") | K44: =IFERROR(AVERAGEIFS($E$11:$E$20,$C$11:$C$20,K$37,$D$11:$D$20,$B44),"") | L44: =IFERROR(AVERAGEIFS($F$11:$F$20,$C$11:$C$20,K$37,$D$11:$D$20,$B44),"") | M44: =IFERROR(AVERAGEIFS($E$11:$E$20,$C$11:$C$20,M$37,$D$11:$D$20,$B44),"") | N44: =IFERROR(AVERAGEIFS($F$11:$F$20,$C$11:$C$20,M$37,$D$11:$D$20,$B44),"")
B45: B7 | C45: =IFERROR(AVERAGEIFS($E$11:$E$20,$C$11:$C$20,C$37,$D$11:$D$20,$B45),"") | D45: =IFERROR(AVERAGEIFS($F$11:$F$20,$C$11:$C$20,C$37,$D$11:$D$20,$B45),"") | E45: =IFERROR(AVERAGEIFS($E$11:$E$20,$C$11:$C$20,E$37,$D$11:$D$20,$B45),"") | F45: =IFERROR(AVERAGEIFS($F$11:$F$20,$C$11:$C$20,E$37,$D$11:$D$20,$B45),"") | G45: =IFERROR(AVERAGEIFS($E$11:$E$20,$C$11:$C$20,G$37,$D$11:$D$20,$B45),"") | H45: =IFERROR(AVERAGEIFS($F$11:$F$20,$C$11:$C$20,G$37,$D$11:$D$20,$B45),"") | I45: =IFERROR(AVERAGEIFS($E$11:$E$20,$C$11:$C$20,I$37,$D$11:$D$20,$B45),"") | J45: =IFERROR(AVERAGEIFS($F$11:$F$20,$C$11:$C$20,I$37,$D$11:$D$20,$B45),"") | K45: =IFERROR(AVERAGEIFS($E$11:$E$20,$C$11:$C$20,K$37,$D$11:$D$20,$B45),"") | L45: =IFERROR(AVERAGEIFS($F$11:$F$20,$C$11:$C$20,K$37,$D$11:$D$20,$B45),"") | M45: =IFERROR(AVERAGEIFS($E$11:$E$20,$C$11:$C$20,M$37,$D$11:$D$20,$B45),"") | N45: =IFERROR(AVERAGEIFS($F$11:$F$20,$C$11:$C$20,M$37,$D$11:$D$20,$B45),"")
B46: B8 | C46: =IFERROR(AVERAGEIFS($E$11:$E$20,$C$11:$C$20,C$37,$D$11:$D$20,$B46),"") | D46: =IFERROR(AVERAGEIFS($F$11:$F$20,$C$11:$C$20,C$37,$D$11:$D$20,$B46),"") | E46: =IFERROR(AVERAGEIFS($E$11:$E$20,$C$11:$C$20,E$37,$D$11:$D$20,$B46),"") | F46: =IFERROR(AVERAGEIFS($F$11:$F$20,$C$11:$C$20,E$37,$D$11:$D$20,$B46),"") | G46: =IFERROR(AVERAGEIFS($E$11:$E$20,$C$11:$C$20,G$37,$D$11:$D$20,$B46),"") | H46: =IFERROR(AVERAGEIFS($F$11:$F$20,$C$11:$C$20,G$37,$D$11:$D$20,$B46),"") | I46: =IFERROR(AVERAGEIFS($E$11:$E$20,$C$11:$C$20,I$37,$D$11:$D$20,$B46),"") | J46: =IFERROR(AVERAGEIFS($F$11:$F$20,$C$11:$C$20,I$37,$D$11:$D$20,$B46),"") | K46: =IFERROR(AVERAGEIFS($E$11:$E$20,$C$11:$C$20,K$37,$D$11:$D$20,$B46),"") | L46: =IFERROR(AVERAGEIFS($F$11:$F$20,$C$11:$C$20,K$37,$D$11:$D$20,$B46),"") | M46: =IFERROR(AVERAGEIFS($E$11:$E$20,$C$11:$C$20,M$37,$D$11:$D$20,$B46),"") | N46: =IFERROR(AVERAGEIFS($F$11:$F$20,$C$11:$C$20,M$37,$D$11:$D$20,$B46),"")
B47: B9 | C47: =IFERROR(AVERAGEIFS($E$11:$E$20,$C$11:$C$20,C$37,$D$11:$D$20,$B47),"") | D47: =IFERROR(AVERAGEIFS($F$11:$F$20,$C$11:$C$20,C$37,$D$11:$D$20,$B47),"") | E47: =IFERROR(AVERAGEIFS($E$11:$E$20,$C$11:$C$20,E$37,$D$11:$D$20,$B47),"") | F47: =IFERROR(AVERAGEIFS($F$11:$F$20,$C$11:$C$20,E$37,$D$11:$D$20,$B47),"") | G47: =IFERROR(AVERAGEIFS($E$11:$E$20,$C$11:$C$20,G$37,$D$11:$D$20,$B47),"") | H47: =IFERROR(AVERAGEIFS($F$11:$F$20,$C$11:$C$20,G$37,$D$11:$D$20,$B47),"") | I47: =IFERROR(AVERAGEIFS($E$11:$E$20,$C$11:$C$20,I$37,$D$11:$D$20,$B47),"") | J47: =IFERROR(AVERAGEIFS($F$11:$F$20,$C$11:$C$20,I$37,$D$11:$D$20,$B47),"") | K47: =IFERROR(AVERAGEIFS($E$11:$E$20,$C$11:$C$20,K$37,$D$11:$D$20,$B47),"") | L47: =IFERROR(AVERAGEIFS($F$11:$F$20,$C$11:$C$20,K$37,$D$11:$D$20,$B47),"") | M47: =IFERROR(AVERAGEIFS($E$11:$E$20,$C$11:$C$20,M$37,$D$11:$D$20,$B47),"") | N47: =IFERROR(AVERAGEIFS($F$11:$F$20,$C$11:$C$20,M$37,$D$11:$D$20,$B47),"")
...
