Workbook

Sheet Cover
B2: ISO37101 assessment
B4: If needed, see the "HowTo" tab for next actions
B6: Content | C6: Review of Aarhus Vision | F6: Summary table: | G6: The following table summarizes the finding of this assessment.
B8: WP | C8: Aarhus | F8: Average Score | G8: Attractiveness | I8: Environment | K8: Resilience | M8: Resources | O8: Cohesion | Q8: Well Being | U8: Review | V8: Content
B9: LL | C9: Content from Vision elements. | G9: Bld. | H9: Neig. | I9: Bld. | J9: Neig. | K9: Bld. | L9: Neig. | M9: Bld. | N9: Neig. | O9: Bld. | P9: Neig. | Q9: Bld. | R9: Neig. | U9: 827d4ae889e4 | V9: Aarhus Living Lab's sustainable initiatives.
B10: Date | C10: July 02, 2024 - 09:47PM | F10: =LEFT(Definitions!B12,25)&"…" -> Governance, empowerment a… | G10: =IFERROR(AVERAGE('827d4ae889e4'!C39,bfe5f797be39!C39,'15370cab949a'!C39),"") | H10: =IFERROR(AVERAGE('827d4ae889e4'!D39,bfe5f797be39!D39,'15370cab949a'!D39),"") | I10: =IFERROR(AVERAGE('827d4ae889e4'!E39,bfe5f797be39!E39,'15370cab949a'!E39),"") | J10: =IFERROR(AVERAGE('827d4ae889e4'!F39,bfe5f797be39!F39,'15370cab949a'!F39),"") | K10: =IFERROR(AVERAGE('827d4ae889e4'!G39,bfe5f797be39!G39,'15370cab949a'!G39),"") | L10: =IFERROR(AVERAGE('827d4ae889e4'!H39,bfe5f797be39!H39,'15370cab949a'!H39),"") | M10: =IFERROR(AVERAGE('827d4ae889e4'!I39,bfe5f797be39!I39,'15370cab949a'!I39),"") | N10: =IFERROR(AVERAGE('827d4ae889e4'!J39,bfe5f797be39!J39,'15370cab949a'!J39),"") | ... R10: =IFERROR(AVERAGE('827d4ae889e4'!N39,bfe5f797be39!N39,'15370cab949a'!N39),"") | U10: bfe5f797be39 | V10: Aarhus University's Living Lab mission: sustainability.
F11: =LEFT(Definitions!B13,25)&"…" -> Education and capacity bu… | G11: =IFERROR(AVERAGE('827d4ae889e4'!C40,bfe5f797be39!C40,'15370cab949a'!C40),"") | H11: =IFERROR(AVERAGE('827d4ae889e4'!D40,bfe5f797be39!D40,'15370cab949a'!D40),"") | I11: =IFERROR(AVERAGE('827d4ae889e4'!E40,bfe5f797be39!E40,'15370cab949a'!E40),"") | J11: =IFERROR(AVERAGE('827d4ae889e4'!F40,bfe5f797be39!F40,'15370cab949a'!F40),"") | K11: =IFERROR(AVERAGE('827d4ae889e4'!G40,bfe5f797be39!G40,'15370cab949a'!G40),"") | L11: =IFERROR(AVERAGE('827d4ae889e4'!H40,bfe5f797be39!H40,'15370cab949a'!H40),"") | M11: =IFERROR(AVERAGE('827d4ae889e4'!I40,bfe5f797be39!I40,'15370cab949a'!I40),"") | N11: =IFERROR(AVERAGE('827d4ae889e4'!J40,bfe5f797be39!J40,'15370cab949a'!J40),"") | ... R11: =IFERROR(AVERAGE('827d4ae889e4'!N40,bfe5f797be39!N40,'15370cab949a'!N40),"") | U11: 15370cab949a | V11: Aarhus Living Lab's sustainable initiatives.
B12: Author(s) | C12: Automated | F12: =LEFT(Definitions!B14,25)&"…" -> Innovation, creativity an… | G12: =IFERROR(AVERAGE('827d4ae889e4'!C41,bfe5f797be39!C41,'15370cab949a'!C41),"") -> 5 | H12: =IFERROR(AVERAGE('827d4ae889e4'!D41,bfe5f797be39!D41,'15370cab949a'!D41),"") | I12: =IFERROR(AVERAGE('827d4ae889e4'!E41,bfe5f797be39!E41,'15370cab949a'!E41),"") | J12: =IFERROR(AVERAGE('827d4ae889e4'!F41,bfe5f797be39!F41,'15370cab949a'!F41),"") | K12: =IFERROR(AVERAGE('827d4ae889e4'!G41,bfe5f797be39!G41,'15370cab949a'!G41),"") | L12: =IFERROR(AVERAGE('827d4ae889e4'!H41,bfe5f797be39!H41,'15370cab949a'!H41),"") | M12: =IFERROR(AVERAGE('827d4ae889e4'!I41,bfe5f797be39!I41,'15370cab949a'!I41),"") | N12: =IFERROR(AVERAGE('827d4ae889e4'!J41,bfe5f797be39!J41,'15370cab949a'!J41),"") | ... R12: =IFERROR(AVERAGE('827d4ae889e4'!N41,bfe5f797be39!N41,'15370cab949a'!N41),"")
F13: =LEFT(Definitions!B15,25)&"…" -> Health and care in the co… | G13: =IFERROR(AVERAGE('827d4ae889e4'!C42,bfe5f797be39!C42,'15370cab949a'!C42),"") | H13: =IFERROR(AVERAGE('827d4ae889e4'!D42,bfe5f797be39!D42,'15370cab949a'!D42),"") | I13: =IFERROR(AVERAGE('827d4ae889e4'!E42,bfe5f797be39!E42,'15370cab949a'!E42),"") | J13: =IFERROR(AVERAGE('827d4ae889e4'!F42,bfe5f797be39!F42,'15370cab949a'!F42),"") | K13: =IFERROR(AVERAGE('827d4ae889e4'!G42,bfe5f797be39!G42,'15370cab949a'!G42),"") | L13: =IFERROR(AVERAGE('827d4ae889e4'!H42,bfe5f797be39!H42,'15370cab949a'!H42),"") | M13: =IFERROR(AVERAGE('827d4ae889e4'!I42,bfe5f797be39!I42,'15370cab949a'!I42),"") | N13: =IFERROR(AVERAGE('827d4ae889e4'!J42,bfe5f797be39!J42,'15370cab949a'!J42),"") | ... R13: =IFERROR(AVERAGE('827d4ae889e4'!N42,bfe5f797be39!N42,'15370cab949a'!N42),"") -> 4
F14: =LEFT(Definitions!B16,25)&"…" -> Culture and community ide… | G14: =IFERROR(AVERAGE('827d4ae889e4'!C43,bfe5f797be39!C43,'15370cab949a'!C43),"") | H14: =IFERROR(AVERAGE('827d4ae889e4'!D43,bfe5f797be39!D43,'15370cab949a'!D43),"") | I14: =IFERROR(AVERAGE('827d4ae889e4'!E43,bfe5f797be39!E43,'15370cab949a'!E43),"") | J14: =IFERROR(AVERAGE('827d4ae889e4'!F43,bfe5f797be39!F43,'15370cab949a'!F43),"") | K14: =IFERROR(AVERAGE('827d4ae889e4'!G43,bfe5f797be39!G43,'15370cab949a'!G43),"") | L14: =IFERROR(AVERAGE('827d4ae889e4'!H43,bfe5f797be39!H43,'15370cab949a'!H43),"") | M14: =IFERROR(AVERAGE('827d4ae889e4'!I43,bfe5f797be39!I43,'15370cab949a'!I43),"") | N14: =IFERROR(AVERAGE('827d4ae889e4'!J43,bfe5f797be39!J43,'15370cab949a'!J43),"") | ... R14: =IFERROR(AVERAGE('827d4ae889e4'!N43,bfe5f797be39!N43,'15370cab949a'!N43),"")
F15: =LEFT(Definitions!B17,25)&"…" -> Living together, interdep… | G15: =IFERROR(AVERAGE('827d4ae889e4'!C44,bfe5f797be39!C44,'15370cab949a'!C44),"") | H15: =IFERROR(AVERAGE('827d4ae889e4'!D44,bfe5f797be39!D44,'15370cab949a'!D44),"") | I15: =IFERROR(AVERAGE('827d4ae889e4'!E44,bfe5f797be39!E44,'15370cab949a'!E44),"") | J15: =IFERROR(AVERAGE('827d4ae889e4'!F44,bfe5f797be39!F44,'15370cab949a'!F44),"") | K15: =IFERROR(AVERAGE('827d4ae889e4'!G44,bfe5f797be39!G44,'15370cab949a'!G44),"") | L15: =IFERROR(AVERAGE('827d4ae889e4'!H44,bfe5f797be39!H44,'15370cab949a'!H44),"") | M15: =IFERROR(AVERAGE('827d4ae889e4'!I44,bfe5f797be39!I44,'15370cab949a'!I44),"") | N15: =IFERROR(AVERAGE('827d4ae889e4'!J44,bfe5f797be39!J44,'15370cab949a'!J44),"") | ... R15: =IFERROR(AVERAGE('827d4ae889e4'!N44,bfe5f797be39!N44,'15370cab949a'!N44),"")
B16: Checked | F16: =LEFT(Definitions!B18,25)&"…" -> Economy and sustainable p… | G16: =IFERROR(AVERAGE('827d4ae889e4'!C45,bfe5f797be39!C45,'15370cab949a'!C45),"") | H16: =IFERROR(AVERAGE('827d4ae889e4'!D45,bfe5f797be39!D45,'15370cab949a'!D45),"") | I16: =IFERROR(AVERAGE('827d4ae889e4'!E45,bfe5f797be39!E45,'15370cab949a'!E45),"") | J16: =IFERROR(AVERAGE('827d4ae889e4'!F45,bfe5f797be39!F45,'15370cab949a'!F45),"") | K16: =IFERROR(AVERAGE('827d4ae889e4'!G45,bfe5f797be39!G45,'15370cab949a'!G45),"") | L16: =IFERROR(AVERAGE('827d4ae889e4'!H45,bfe5f797be39!H45,'15370cab949a'!H45),"") | M16: =IFERROR(AVERAGE('827d4ae889e4'!I45,bfe5f797be39!I45,'15370cab949a'!I45),"") | N16: =IFERROR(AVERAGE('827d4ae889e4'!J45,bfe5f797be39!J45,'15370cab949a'!J45),"") | ... R16: =IFERROR(AVERAGE('827d4ae889e4'!N45,bfe5f797be39!N45,'15370cab949a'!N45),"")
F17: =LEFT(Definitions!B19,25)&"…" -> Living and working enviro… | G17: =IFERROR(AVERAGE('827d4ae889e4'!C46,bfe5f797be39!C46,'15370cab949a'!C46),"") | H17: =IFERROR(AVERAGE('827d4ae889e4'!D46,bfe5f797be39!D46,'15370cab949a'!D46),"") | I17: =IFERROR(AVERAGE('827d4ae889e4'!E46,bfe5f797be39!E46,'15370cab949a'!E46),"") | J17: =IFERROR(AVERAGE('827d4ae889e4'!F46,bfe5f797be39!F46,'15370cab949a'!F46),"") | K17: =IFERROR(AVERAGE('827d4ae889e4'!G46,bfe5f797be39!G46,'15370cab949a'!G46),"") | L17: =IFERROR(AVERAGE('827d4ae889e4'!H46,bfe5f797be39!H46,'15370cab949a'!H46),"") | M17: =IFERROR(AVERAGE('827d4ae889e4'!I46,bfe5f797be39!I46,'15370cab949a'!I46),"") -> 3 | N17: =IFERROR(AVERAGE('827d4ae889e4'!J46,bfe5f797be39!J46,'15370cab949a'!J46),"") -> 3 | ... R17: =IFERROR(AVERAGE('827d4ae889e4'!N46,bfe5f797be39!N46,'15370cab949a'!N46),"")
F18: =LEFT(Definitions!B20,25)&"…" -> Safety and security… | G18: =IFERROR(AVERAGE('827d4ae889e4'!C47,bfe5f797be39!C47,'15370cab949a'!C47),"") | H18: =IFERROR(AVERAGE('827d4ae889e4'!D47,bfe5f797be39!D47,'15370cab949a'!D47),"") | I18: =IFERROR(AVERAGE('827d4ae889e4'!E47,bfe5f797be39!E47,'15370cab949a'!E47),"") | J18: =IFERROR(AVERAGE('827d4ae889e4'!F47,bfe5f797be39!F47,'15370cab949a'!F47),"") | K18: =IFERROR(AVERAGE('827d4ae889e4'!G47,bfe5f797be39!G47,'15370cab949a'!G47),"") | L18: =IFERROR(AVERAGE('827d4ae889e4'!H47,bfe5f797be39!H47,'15370cab949a'!H47),"") | M18: =IFERROR(AVERAGE('827d4ae889e4'!I47,bfe5f797be39!I47,'15370cab949a'!I47),"") | N18: =IFERROR(AVERAGE('827d4ae889e4'!J47,bfe5f797be39!J47,'15370cab949a'!J47),"") | ... R18: =IFERROR(AVERAGE('827d4ae889e4'!N47,bfe5f797be39!N47,'15370cab949a'!N47),"")
F19: =LEFT(Definitions!B21,25)&"…" -> Biodiversity and ecosyste… | G19: =IFERROR(AVERAGE('827d4ae889e4'!C48,bfe5f797be39!C48,'15370cab949a'!C48),"") | H19: =IFERROR(AVERAGE('827d4ae889e4'!D48,bfe5f797be39!D48,'15370cab949a'!D48),"") | I19: =IFERROR(AVERAGE('827d4ae889e4'!E48,bfe5f797be39!E48,'15370cab949a'!E48),"") -> 4 | J19: =IFERROR(AVERAGE('827d4ae889e4'!F48,bfe5f797be39!F48,'15370cab949a'!F48),"") | K19: =IFERROR(AVERAGE('827d4ae889e4'!G48,bfe5f797be39!G48,'15370cab949a'!G48),"") | L19: =IFERROR(AVERAGE('827d4ae889e4'!H48,bfe5f797be39!H48,'15370cab949a'!H48),"") -> 4 | M19: =IFERROR(AVERAGE('827d4ae889e4'!I48,bfe5f797be39!I48,'15370cab949a'!I48),"") -> 4 | N19: =IFERROR(AVERAGE('827d4ae889e4'!J48,bfe5f797be39!J48,'15370cab949a'!J48),"") | ... R19: =IFERROR(AVERAGE('827d4ae889e4'!N48,bfe5f797be39!N48,'15370cab949a'!N48),"")
B20: Validated | F20: =LEFT(Definitions!B22,25)&"…" -> Community smart infrastru… | G20: =IFERROR(AVERAGE('827d4ae889e4'!C49,bfe5f797be39!C49,'15370cab949a'!C49),"") | H20: =IFERROR(AVERAGE('827d4ae889e4'!D49,bfe5f797be39!D49,'15370cab949a'!D49),"") | I20: =IFERROR(AVERAGE('827d4ae889e4'!E49,bfe5f797be39!E49,'15370cab949a'!E49),"") | J20: =IFERROR(AVERAGE('827d4ae889e4'!F49,bfe5f797be39!F49,'15370cab949a'!F49),"") | K20: =IFERROR(AVERAGE('827d4ae889e4'!G49,bfe5f797be39!G49,'15370cab949a'!G49),"") | L20: =IFERROR(AVERAGE('827d4ae889e4'!H49,bfe5f797be39!H49,'15370cab949a'!H49),"") -> 4 | M20: =IFERROR(AVERAGE('827d4ae889e4'!I49,bfe5f797be39!I49,'15370cab949a'!I49),"") | N20: =IFERROR(AVERAGE('827d4ae889e4'!J49,bfe5f797be39!J49,'15370cab949a'!J49),"") | ... R20: =IFERROR(AVERAGE('827d4ae889e4'!N49,bfe5f797be39!N49,'15370cab949a'!N49),"")
F21: =LEFT(Definitions!B23,25)&"…" -> Mobility… | G21: =IFERROR(AVERAGE('827d4ae889e4'!C50,bfe5f797be39!C50,'15370cab949a'!C50),"") | H21: =IFERROR(AVERAGE('827d4ae889e4'!D50,bfe5f797be39!D50,'15370cab949a'!D50),"") | I21: =IFERROR(AVERAGE('827d4ae889e4'!E50,bfe5f797be39!E50,'15370cab949a'!E50),"") | J21: =IFERROR(AVERAGE('827d4ae889e4'!F50,bfe5f797be39!F50,'15370cab949a'!F50),"") | K21: =IFERROR(AVERAGE('827d4ae889e4'!G50,bfe5f797be39!G50,'15370cab949a'!G50),"") | L21: =IFERROR(AVERAGE('827d4ae889e4'!H50,bfe5f797be39!H50,'15370cab949a'!H50),"") | M21: =IFERROR(AVERAGE('827d4ae889e4'!I50,bfe5f797be39!I50,'15370cab949a'!I50),"") | N21: =IFERROR(AVERAGE('827d4ae889e4'!J50,bfe5f797be39!J50,'15370cab949a'!J50),"") | ... R21: =IFERROR(AVERAGE('827d4ae889e4'!N50,bfe5f797be39!N50,'15370cab949a'!N50),"")
B24: Version of tool | C24: (10/04/2024) | F24: Number of count | G24: Attractiveness | I24: Environment | K24: Resilience | M24: Resources | O24: Cohesion | Q24: Well Being
G25: Bld. | H25: Neig. | I25: Bld. | J25: Neig. | K25: Bld. | L25: Neig. | M25: Bld. | N25: Neig. | O25: Bld. | P25: Neig. | Q25: Bld. | R25: Neig.
F26: =F10 -> Governance, empowerment a… | G26: =IF(ISNUMBER('827d4ae889e4'!C39)+ISNUMBER(bfe5f797be39!C39)+ISNUMBER('15370cab949a'!C39),ISNUMBER('827d4ae889e4'!C39)+ISNUMBER(bfe5f797be39!C39)+ISNUMBER('15370cab949a'!C39),"") | H26: =IF(ISNUMBER('827d4ae889e4'!D39)+ISNUMBER(bfe5f797be39!D39)+ISNUMBER('15370cab949a'!D39),ISNUMBER('827d4ae889e4'!D39)+ISNUMBER(bfe5f797be39!D39)+ISNUMBER('15370cab949a'!D39),"") | I26: =IF(ISNUMBER('827d4ae889e4'!E39)+ISNUMBER(bfe5f797be39!E39)+ISNUMBER('15370cab949a'!E39),ISNUMBER('827d4ae889e4'!E39)+ISNUMBER(bfe5f797be39!E39)+ISNUMBER('15370cab949a'!E39),"") | J26: =IF(ISNUMBER('827d4ae889e4'!F39)+ISNUMBER(bfe5f797be39!F39)+ISNUMBER('15370cab949a'!F39),ISNUMBER('827d4ae889e4'!F39)+ISNUMBER(bfe5f797be39!F39)+ISNUMBER('15370cab949a'!F39),"") | K26: =IF(ISNUMBER('827d4ae889e4'!G39)+ISNUMBER(bfe5f797be39!G39)+ISNUMBER('15370cab949a'!G39),ISNUMBER('827d4ae889e4'!G39)+ISNUMBER(bfe5f797be39!G39)+ISNUMBER('15370cab949a'!G39),"") | L26: =IF(ISNUMBER('827d4ae889e4'!H39)+ISNUMBER(bfe5f797be39!H39)+ISNUMBER('15370cab949a'!H39),ISNUMBER('827d4ae889e4'!H39)+ISNUMBER(bfe5f797be39!H39)+ISNUMBER('15370cab949a'!H39),"") | M26: =IF(ISNUMBER('827d4ae889e4'!I39)+ISNUMBER(bfe5f797be39!I39)+ISNUMBER('15370cab949a'!I39),ISNUMBER('827d4ae889e4'!I39)+ISNUMBER(bfe5f797be39!I39)+ISNUMBER('15370cab949a'!I39),"") | N26: =IF(ISNUMBER('827d4ae889e4'!J39)+ISNUMBER(bfe5f797be39!J39)+ISNUMBER('15370cab949a'!J39),ISNUMBER('827d4ae889e4'!J39)+ISNUMBER(bfe5f797be39!J39)+ISNUMBER('15370cab949a'!J39),"") | ... R26: =IF(ISNUMBER('827d4ae889e4'!N39)+ISNUMBER(bfe5f797be39!N39)+ISNUMBER('15370cab949a'!N39),ISNUMBER('827d4ae889e4'!N39)+ISNUMBER(bfe5f797be39!N39)+ISNUMBER('15370cab949a'!N39),"")
F27: =F11 -> Education and capacity bu… | G27: =IF(ISNUMBER('827d4ae889e4'!C40)+ISNUMBER(bfe5f797be39!C40)+ISNUMBER('15370cab949a'!C40),ISNUMBER('827d4ae889e4'!C40)+ISNUMBER(bfe5f797be39!C40)+ISNUMBER('15370cab949a'!C40),"") | H27: =IF(ISNUMBER('827d4ae889e4'!D40)+ISNUMBER(bfe5f797be39!D40)+ISNUMBER('15370cab949a'!D40),ISNUMBER('827d4ae889e4'!D40)+ISNUMBER(bfe5f797be39!D40)+ISNUMBER('15370cab949a'!D40),"") | I27: =IF(ISNUMBER('827d4ae889e4'!E40)+ISNUMBER(bfe5f797be39!E40)+ISNUMBER('15370cab949a'!E40),ISNUMBER('827d4ae889e4'!E40)+ISNUMBER(bfe5f797be39!E40)+ISNUMBER('15370cab949a'!E40),"") | J27: =IF(ISNUMBER('827d4ae889e4'!F40)+ISNUMBER(bfe5f797be39!F40)+ISNUMBER('15370cab949a'!F40),ISNUMBER('827d4ae889e4'!F40)+ISNUMBER(bfe5f797be39!F40)+ISNUMBER('15370cab949a'!F40),"") | K27: =IF(ISNUMBER('827d4ae889e4'!G40)+ISNUMBER(bfe5f797be39!G40)+ISNUMBER('15370cab949a'!G40),ISNUMBER('827d4ae889e4'!G40)+ISNUMBER(bfe5f797be39!G40)+ISNUMBER('15370cab949a'!G40),"") | L27: =IF(ISNUMBER('827d4ae889e4'!H40)+ISNUMBER(bfe5f797be39!H40)+ISNUMBER('15370cab949a'!H40),ISNUMBER('827d4ae889e4'!H40)+ISNUMBER(bfe5f797be39!H40)+ISNUMBER('15370cab949a'!H40),"") | M27: =IF(ISNUMBER('827d4ae889e4'!I40)+ISNUMBER(bfe5f797be39!I40)+ISNUMBER('15370cab949a'!I40),ISNUMBER('827d4ae889e4'!I40)+ISNUMBER(bfe5f797be39!I40)+ISNUMBER('15370cab949a'!I40),"") | N27: =IF(ISNUMBER('827d4ae889e4'!J40)+ISNUMBER(bfe5f797be39!J40)+ISNUMBER('15370cab949a'!J40),ISNUMBER('827d4ae889e4'!J40)+ISNUMBER(bfe5f797be39!J40)+ISNUMBER('15370cab949a'!J40),"") | ... R27: =IF(ISNUMBER('827d4ae889e4'!N40)+ISNUMBER(bfe5f797be39!N40)+ISNUMBER('15370cab949a'!N40),ISNUMBER('827d4ae889e4'!N40)+ISNUMBER(bfe5f797be39!N40)+ISNUMBER('15370cab949a'!N40),"")
F28: =F12 -> Innovation, creativity an… | G28: =IF(ISNUMBER('827d4ae889e4'!C41)+ISNUMBER(bfe5f797be39!C41)+ISNUMBER('15370cab949a'!C41),ISNUMBER('827d4ae889e4'!C41)+ISNUMBER(bfe5f797be39!C41)+ISNUMBER('15370cab949a'!C41),"") -> 3 | H28: =IF(ISNUMBER('827d4ae889e4'!D41)+ISNUMBER(bfe5f797be39!D41)+ISNUMBER('15370cab949a'!D41),ISNUMBER('827d4ae889e4'!D41)+ISNUMBER(bfe5f797be39!D41)+ISNUMBER('15370cab949a'!D41),"") | I28: =IF(ISNUMBER('827d4ae889e4'!E41)+ISNUMBER(bfe5f797be39!E41)+ISNUMBER('15370cab949a'!E41),ISNUMBER('827d4ae889e4'!E41)+ISNUMBER(bfe5f797be39!E41)+ISNUMBER('15370cab949a'!E41),"") | J28: =IF(ISNUMBER('827d4ae889e4'!F41)+ISNUMBER(bfe5f797be39!F41)+ISNUMBER('15370cab949a'!F41),ISNUMBER('827d4ae889e4'!F41)+ISNUMBER(bfe5f797be39!F41)+ISNUMBER('15370cab949a'!F41),"") | K28: =IF(ISNUMBER('827d4ae889e4'!G41)+ISNUMBER(bfe5f797be39!G41)+ISNUMBER('15370cab949a'!G41),ISNUMBER('827d4ae889e4'!G41)+ISNUMBER(bfe5f797be39!G41)+ISNUMBER('15370cab949a'!G41),"") | L28: =IF(ISNUMBER('827d4ae889e4'!H41)+ISNUMBER(bfe5f797be39!H41)+ISNUMBER('15370cab949a'!H41),ISNUMBER('827d4ae889e4'!H41)+ISNUMBER(bfe5f797be39!H41)+ISNUMBER('15370cab949a'!H41),"") | M28: =IF(ISNUMBER('827d4ae889e4'!I41)+ISNUMBER(bfe5f797be39!I41)+ISNUMBER('15370cab949a'!I41),ISNUMBER('827d4ae889e4'!I41)+ISNUMBER(bfe5f797be39!I41)+ISNUMBER('15370cab949a'!I41),"") | N28: =IF(ISNUMBER('827d4ae889e4'!J41)+ISNUMBER(bfe5f797be39!J41)+ISNUMBER('15370cab949a'!J41),ISNUMBER('827d4ae889e4'!J41)+ISNUMBER(bfe5f797be39!J41)+ISNUMBER('15370cab949a'!J41),"") | ... R28: =IF(ISNUMBER('827d4ae889e4'!N41)+ISNUMBER(bfe5f797be39!N41)+ISNUMBER('15370cab949a'!N41),ISNUMBER('827d4ae889e4'!N41)+ISNUMBER(bfe5f797be39!N41)+ISNUMBER('15370cab949a'!N41),"")
F29: =F13 -> Health and care in the co… | G29: =IF(ISNUMBER('827d4ae889e4'!C42)+ISNUMBER(bfe5f797be39!C42)+ISNUMBER('15370cab949a'!C42),ISNUMBER('827d4ae889e4'!C42)+ISNUMBER(bfe5f797be39!C42)+ISNUMBER('15370cab949a'!C42),"") | H29: =IF(ISNUMBER('827d4ae889e4'!D42)+ISNUMBER(bfe5f797be39!D42)+ISNUMBER('15370cab949a'!D42),ISNUMBER('827d4ae889e4'!D42)+ISNUMBER(bfe5f797be39!D42)+ISNUMBER('15370cab949a'!D42),"") | I29: =IF(ISNUMBER('827d4ae889e4'!E42)+ISNUMBER(bfe5f797be39!E42)+ISNUMBER('15370cab949a'!E42),ISNUMBER('827d4ae889e4'!E42)+ISNUMBER(bfe5f797be39!E42)+ISNUMBER('15370cab949a'!E42),"") | J29: =IF(ISNUMBER('827d4ae889e4'!F42)+ISNUMBER(bfe5f797be39!F42)+ISNUMBER('15370cab949a'!F42),ISNUMBER('827d4ae889e4'!F42)+ISNUMBER(bfe5f797be39!F42)+ISNUMBER('15370cab949a'!F42),"") | K29: =IF(ISNUMBER('827d4ae889e4'!G42)+ISNUMBER(bfe5f797be39!G42)+ISNUMBER('15370cab949a'!G42),ISNUMBER('827d4ae889e4'!G42)+ISNUMBER(bfe5f797be39!G42)+ISNUMBER('15370cab949a'!G42),"") | L29: =IF(ISNUMBER('827d4ae889e4'!H42)+ISNUMBER(bfe5f797be39!H42)+ISNUMBER('15370cab949a'!H42),ISNUMBER('827d4ae889e4'!H42)+ISNUMBER(bfe5f797be39!H42)+ISNUMBER('15370cab949a'!H42),"") | M29: =IF(ISNUMBER('827d4ae889e4'!I42)+ISNUMBER(bfe5f797be39!I42)+ISNUMBER('15370cab949a'!I42),ISNUMBER('827d4ae889e4'!I42)+ISNUMBER(bfe5f797be39!I42)+ISNUMBER('15370cab949a'!I42),"") | N29: =IF(ISNUMBER('827d4ae889e4'!J42)+ISNUMBER(bfe5f797be39!J42)+ISNUMBER('15370cab949a'!J42),ISNUMBER('827d4ae889e4'!J42)+ISNUMBER(bfe5f797be39!J42)+ISNUMBER('15370cab949a'!J42),"") | ... R29: =IF(ISNUMBER('827d4ae889e4'!N42)+ISNUMBER(bfe5f797be39!N42)+ISNUMBER('15370cab949a'!N42),ISNUMBER('827d4ae889e4'!N42)+ISNUMBER(bfe5f797be39!N42)+ISNUMBER('15370cab949a'!N42),"") -> 2
F30: =F14 -> Culture and community ide… | G30: =IF(ISNUMBER('827d4ae889e4'!C43)+ISNUMBER(bfe5f797be39!C43)+ISNUMBER('15370cab949a'!C43),ISNUMBER('827d4ae889e4'!C43)+ISNUMBER(bfe5f797be39!C43)+ISNUMBER('15370cab949a'!C43),"") | H30: =IF(ISNUMBER('827d4ae889e4'!D43)+ISNUMBER(bfe5f797be39!D43)+ISNUMBER('15370cab949a'!D43),ISNUMBER('827d4ae889e4'!D43)+ISNUMBER(bfe5f797be39!D43)+ISNUMBER('15370cab949a'!D43),"") | I30: =IF(ISNUMBER('827d4ae889e4'!E43)+ISNUMBER(bfe5f797be39!E43)+ISNUMBER('15370cab949a'!E43),ISNUMBER('827d4ae889e4'!E43)+ISNUMBER(bfe5f797be39!E43)+ISNUMBER('15370cab949a'!E43),"") | J30: =IF(ISNUMBER('827d4ae889e4'!F43)+ISNUMBER(bfe5f797be39!F43)+ISNUMBER('15370cab949a'!F43),ISNUMBER('827d4ae889e4'!F43)+ISNUMBER(bfe5f797be39!F43)+ISNUMBER('15370cab949a'!F43),"") | K30: =IF(ISNUMBER('827d4ae889e4'!G43)+ISNUMBER(bfe5f797be39!G43)+ISNUMBER('15370cab949a'!G43),ISNUMBER('827d4ae889e4'!G43)+ISNUMBER(bfe5f797be39!G43)+ISNUMBER('15370cab949a'!G43),"") | L30: =IF(ISNUMBER('827d4ae889e4'!H43)+ISNUMBER(bfe5f797be39!H43)+ISNUMBER('15370cab949a'!H43),ISNUMBER('827d4ae889e4'!H43)+ISNUMBER(bfe5f797be39!H43)+ISNUMBER('15370cab949a'!H43),"") | M30: =IF(ISNUMBER('827d4ae889e4'!I43)+ISNUMBER(bfe5f797be39!I43)+ISNUMBER('15370cab949a'!I43),ISNUMBER('827d4ae889e4'!I43)+ISNUMBER(bfe5f797be39!I43)+ISNUMBER('15370cab949a'!I43),"") | N30: =IF(ISNUMBER('827d4ae889e4'!J43)+ISNUMBER(bfe5f797be39!J43)+ISNUMBER('15370cab949a'!J43),ISNUMBER('827d4ae889e4'!J43)+ISNUMBER(bfe5f797be39!J43)+ISNUMBER('15370cab949a'!J43),"") | ... R30: =IF(ISNUMBER('827d4ae889e4'!N43)+ISNUMBER(bfe5f797be39!N43)+ISNUMBER('15370cab949a'!N43),ISNUMBER('827d4ae889e4'!N43)+ISNUMBER(bfe5f797be39!N43)+ISNUMBER('15370cab949a'!N43),"")
F31: =F15 -> Living together, interdep… | G31: =IF(ISNUMBER('827d4ae889e4'!C44)+ISNUMBER(bfe5f797be39!C44)+ISNUMBER('15370cab949a'!C44),ISNUMBER('827d4ae889e4'!C44)+ISNUMBER(bfe5f797be39!C44)+ISNUMBER('15370cab949a'!C44),"") | H31: =IF(ISNUMBER('827d4ae889e4'!D44)+ISNUMBER(bfe5f797be39!D44)+ISNUMBER('15370cab949a'!D44),ISNUMBER('827d4ae889e4'!D44)+ISNUMBER(bfe5f797be39!D44)+ISNUMBER('15370cab949a'!D44),"") | I31: =IF(ISNUMBER('827d4ae889e4'!E44)+ISNUMBER(bfe5f797be39!E44)+ISNUMBER('15370cab949a'!E44),ISNUMBER('827d4ae889e4'!E44)+ISNUMBER(bfe5f797be39!E44)+ISNUMBER('15370cab949a'!E44),"") | J31: =IF(ISNUMBER('827d4ae889e4'!F44)+ISNUMBER(bfe5f797be39!F44)+ISNUMBER('15370cab949a'!F44),ISNUMBER('827d4ae889e4'!F44)+ISNUMBER(bfe5f797be39!F44)+ISNUMBER('15370cab949a'!F44),"") | K31: =IF(ISNUMBER('827d4ae889e4'!G44)+ISNUMBER(bfe5f797be39!G44)+ISNUMBER('15370cab949a'!G44),ISNUMBER('827d4ae889e4'!G44)+ISNUMBER(bfe5f797be39!G44)+ISNUMBER('15370cab949a'!G44),"") | L31: =IF(ISNUMBER('827d4ae889e4'!H44)+ISNUMBER(bfe5f797be39!H44)+ISNUMBER('15370cab949a'!H44),ISNUMBER('827d4ae889e4'!H44)+ISNUMBER(bfe5f797be39!H44)+ISNUMBER('15370cab949a'!H44),"") | M31: =IF(ISNUMBER('827d4ae889e4'!I44)+ISNUMBER(bfe5f797be39!I44)+ISNUMBER('15370cab949a'!I44),ISNUMBER('827d4ae889e4'!I44)+ISNUMBER(bfe5f797be39!I44)+ISNUMBER('15370cab949a'!I44),"") | N31: =IF(ISNUMBER('827d4ae889e4'!J44)+ISNUMBER(bfe5f797be39!J44)+ISNUMBER('15370cab949a'!J44),ISNUMBER('827d4ae889e4'!J44)+ISNUMBER(bfe5f797be39!J44)+ISNUMBER('15370cab949a'!J44),"") | ... R31: =IF(ISNUMBER('827d4ae889e4'!N44)+ISNUMBER(bfe5f797be39!N44)+ISNUMBER('15370cab949a'!N44),ISNUMBER('827d4ae889e4'!N44)+ISNUMBER(bfe5f797be39!N44)+ISNUMBER('15370cab949a'!N44),"")
F32: =F16 -> Economy and sustainable p… | G32: =IF(ISNUMBER('827d4ae889e4'!C45)+ISNUMBER(bfe5f797be39!C45)+ISNUMBER('15370cab949a'!C45),ISNUMBER('827d4ae889e4'!C45)+ISNUMBER(bfe5f797be39!C45)+ISNUMBER('15370cab949a'!C45),"") | H32: =IF(ISNUMBER('827d4ae889e4'!D45)+ISNUMBER(bfe5f797be39!D45)+ISNUMBER('15370cab949a'!D45),ISNUMBER('827d4ae889e4'!D45)+ISNUMBER(bfe5f797be39!D45)+ISNUMBER('15370cab949a'!D45),"") | I32: =IF(ISNUMBER('827d4ae889e4'!E45)+ISNUMBER(bfe5f797be39!E45)+ISNUMBER('15370cab949a'!E45),ISNUMBER('827d4ae889e4'!E45)+ISNUMBER(bfe5f797be39!E45)+ISNUMBER('15370cab949a'!E45),"") | J32: =IF(ISNUMBER('827d4ae889e4'!F45)+ISNUMBER(bfe5f797be39!F45)+ISNUMBER('15370cab949a'!F45),ISNUMBER('827d4ae889e4'!F45)+ISNUMBER(bfe5f797be39!F45)+ISNUMBER('15370cab949a'!F45),"") | K32: =IF(ISNUMBER('827d4ae889e4'!G45)+ISNUMBER(bfe5f797be39!G45)+ISNUMBER('15370cab949a'!G45),ISNUMBER('827d4ae889e4'!G45)+ISNUMBER(bfe5f797be39!G45)+ISNUMBER('15370cab949a'!G45),"") | L32: =IF(ISNUMBER('827d4ae889e4'!H45)+ISNUMBER(bfe5f797be39!H45)+ISNUMBER('15370cab949a'!H45),ISNUMBER('827d4ae889e4'!H45)+ISNUMBER(bfe5f797be39!H45)+ISNUMBER('15370cab949a'!H45),"") | M32: =IF(ISNUMBER('827d4ae889e4'!I45)+ISNUMBER(bfe5f797be39!I45)+ISNUMBER('15370cab949a'!I45),ISNUMBER('827d4ae889e4'!I45)+ISNUMBER(bfe5f797be39!I45)+ISNUMBER('15370cab949a'!I45),"") | N32: =IF(ISNUMBER('827d4ae889e4'!J45)+ISNUMBER(bfe5f797be39!J45)+ISNUMBER('15370cab949a'!J45),ISNUMBER('827d4ae889e4'!J45)+ISNUMBER(bfe5f797be39!J45)+ISNUMBER('15370cab949a'!J45),"") | ... R32: =IF(ISNUMBER('827d4ae889e4'!N45)+ISNUMBER(bfe5f797be39!N45)+ISNUMBER('15370cab949a'!N45),ISNUMBER('827d4ae889e4'!N45)+ISNUMBER(bfe5f797be39!N45)+ISNUMBER('15370cab949a'!N45),"")
F33: =F17 -> Living and working enviro… | G33: =IF(ISNUMBER('827d4ae889e4'!C46)+ISNUMBER(bfe5f797be39!C46)+ISNUMBER('15370cab949a'!C46),ISNUMBER('827d4ae889e4'!C46)+ISNUMBER(bfe5f797be39!C46)+ISNUMBER('15370cab949a'!C46),"") | H33: =IF(ISNUMBER('827d4ae889e4'!D46)+ISNUMBER(bfe5f797be39!D46)+ISNUMBER('15370cab949a'!D46),ISNUMBER('827d4ae889e4'!D46)+ISNUMBER(bfe5f797be39!D46)+ISNUMBER('15370cab949a'!D46),"") | I33: =IF(ISNUMBER('827d4ae889e4'!E46)+ISNUMBER(bfe5f797be39!E46)+ISNUMBER('15370cab949a'!E46),ISNUMBER('827d4ae889e4'!E46)+ISNUMBER(bfe5f797be39!E46)+ISNUMBER('15370cab949a'!E46),"") | J33: =IF(ISNUMBER('827d4ae889e4'!F46)+ISNUMBER(bfe5f797be39!F46)+ISNUMBER('15370cab949a'!F46),ISNUMBER('827d4ae889e4'!F46)+ISNUMBER(bfe5f797be39!F46)+ISNUMBER('15370cab949a'!F46),"") | K33: =IF(ISNUMBER('827d4ae889e4'!G46)+ISNUMBER(bfe5f797be39!G46)+ISNUMBER('15370cab949a'!G46),ISNUMBER('827d4ae889e4'!G46)+ISNUMBER(bfe5f797be39!G46)+ISNUMBER('15370cab949a'!G46),"") | L33: =IF(ISNUMBER('827d4ae889e4'!H46)+ISNUMBER(bfe5f797be39!H46)+ISNUMBER('15370cab949a'!H46),ISNUMBER('827d4ae889e4'!H46)+ISNUMBER(bfe5f797be39!H46)+ISNUMBER('15370cab949a'!H46),"") | M33: =IF(ISNUMBER('827d4ae889e4'!I46)+ISNUMBER(bfe5f797be39!I46)+ISNUMBER('15370cab949a'!I46),ISNUMBER('827d4ae889e4'!I46)+ISNUMBER(bfe5f797be39!I46)+ISNUMBER('15370cab949a'!I46),"") -> 1 | N33: =IF(ISNUMBER('827d4ae889e4'!J46)+ISNUMBER(bfe5f797be39!J46)+ISNUMBER('15370cab949a'!J46),ISNUMBER('827d4ae889e4'!J46)+ISNUMBER(bfe5f797be39!J46)+ISNUMBER('15370cab949a'!J46),"") -> 2 | ... R33: =IF(ISNUMBER('827d4ae889e4'!N46)+ISNUMBER(bfe5f797be39!N46)+ISNUMBER('15370cab949a'!N46),ISNUMBER('827d4ae889e4'!N46)+ISNUMBER(bfe5f797be39!N46)+ISNUMBER('15370cab949a'!N46),"")
F34: =F18 -> Safety and security… | G34: =IF(ISNUMBER('827d4ae889e4'!C47)+ISNUMBER(bfe5f797be39!C47)+ISNUMBER('15370cab949a'!C47),ISNUMBER('827d4ae889e4'!C47)+ISNUMBER(bfe5f797be39!C47)+ISNUMBER('15370cab949a'!C47),"") | H34: =IF(ISNUMBER('827d4ae889e4'!D47)+ISNUMBER(bfe5f797be39!D47)+ISNUMBER('15370cab949a'!D47),ISNUMBER('827d4ae889e4'!D47)+ISNUMBER(bfe5f797be39!D47)+ISNUMBER('15370cab949a'!D47),"") | I34: =IF(ISNUMBER('827d4ae889e4'!E47)+ISNUMBER(bfe5f797be39!E47)+ISNUMBER('15370cab949a'!E47),ISNUMBER('827d4ae889e4'!E47)+ISNUMBER(bfe5f797be39!E47)+ISNUMBER('15370cab949a'!E47),"") | J34: =IF(ISNUMBER('827d4ae889e4'!F47)+ISNUMBER(bfe5f797be39!F47)+ISNUMBER('15370cab949a'!F47),ISNUMBER('827d4ae889e4'!F47)+ISNUMBER(bfe5f797be39!F47)+ISNUMBER('15370cab949a'!F47),"") | K34: =IF(ISNUMBER('827d4ae889e4'!G47)+ISNUMBER(bfe5f797be39!G47)+ISNUMBER('15370cab949a'!G47),ISNUMBER('827d4ae889e4'!G47)+ISNUMBER(bfe5f797be39!G47)+ISNUMBER('15370cab949a'!G47),"") | L34: =IF(ISNUMBER('827d4ae889e4'!H47)+ISNUMBER(bfe5f797be39!H47)+ISNUMBER('15370cab949a'!H47),ISNUMBER('827d4ae889e4'!H47)+ISNUMBER(bfe5f797be39!H47)+ISNUMBER('15370cab949a'!H47),"") | M34: =IF(ISNUMBER('827d4ae889e4'!I47)+ISNUMBER(bfe5f797be39!I47)+ISNUMBER('15370cab949a'!I47),ISNUMBER('827d4ae889e4'!I47)+ISNUMBER(bfe5f797be39!I47)+ISNUMBER('15370cab949a'!I47),"") | N34: =IF(ISNUMBER('827d4ae889e4'!J47)+ISNUMBER(bfe5f797be39!J47)+ISNUMBER('15370cab949a'!J47),ISNUMBER('827d4ae889e4'!J47)+ISNUMBER(bfe5f797be39!J47)+ISNUMBER('15370cab949a'!J47),"") | ... R34: =IF(ISNUMBER('827d4ae889e4'!N47)+ISNUMBER(bfe5f797be39!N47)+ISNUMBER('15370cab949a'!N47),ISNUMBER('827d4ae889e4'!N47)+ISNUMBER(bfe5f797be39!N47)+ISNUMBER('15370cab949a'!N47),"")
F35: =F19 -> Biodiversity and ecosyste… | G35: =IF(ISNUMBER('827d4ae889e4'!C48)+ISNUMBER(bfe5f797be39!C48)+ISNUMBER('15370cab949a'!C48),ISNUMBER('827d4ae889e4'!C48)+ISNUMBER(bfe5f797be39!C48)+ISNUMBER('15370cab949a'!C48),"") | H35: =IF(ISNUMBER('827d4ae889e4'!D48)+ISNUMBER(bfe5f797be39!D48)+ISNUMBER('15370cab949a'!D48),ISNUMBER('827d4ae889e4'!D48)+ISNUMBER(bfe5f797be39!D48)+ISNUMBER('15370cab949a'!D48),"") | I35: =IF(ISNUMBER('827d4ae889e4'!E48)+ISNUMBER(bfe5f797be39!E48)+ISNUMBER('15370cab949a'!E48),ISNUMBER('827d4ae889e4'!E48)+ISNUMBER(bfe5f797be39!E48)+ISNUMBER('15370cab949a'!E48),"") -> 1 | J35: =IF(ISNUMBER('827d4ae889e4'!F48)+ISNUMBER(bfe5f797be39!F48)+ISNUMBER('15370cab949a'!F48),ISNUMBER('827d4ae889e4'!F48)+ISNUMBER(bfe5f797be39!F48)+ISNUMBER('15370cab949a'!F48),"") | K35: =IF(ISNUMBER('827d4ae889e4'!G48)+ISNUMBER(bfe5f797be39!G48)+ISNUMBER('15370cab949a'!G48),ISNUMBER('827d4ae889e4'!G48)+ISNUMBER(bfe5f797be39!G48)+ISNUMBER('15370cab949a'!G48),"") | L35: =IF(ISNUMBER('827d4ae889e4'!H48)+ISNUMBER(bfe5f797be39!H48)+ISNUMBER('15370cab949a'!H48),ISNUMBER('827d4ae889e4'!H48)+ISNUMBER(bfe5f797be39!H48)+ISNUMBER('15370cab949a'!H48),"") -> 2 | M35: =IF(ISNUMBER('827d4ae889e4'!I48)+ISNUMBER(bfe5f797be39!I48)+ISNUMBER('15370cab949a'!I48),ISNUMBER('827d4ae889e4'!I48)+ISNUMBER(bfe5f797be39!I48)+ISNUMBER('15370cab949a'!I48),"") -> 1 | N35: =IF(ISNUMBER('827d4ae889e4'!J48)+ISNUMBER(bfe5f797be39!J48)+ISNUMBER('15370cab949a'!J48),ISNUMBER('827d4ae889e4'!J48)+ISNUMBER(bfe5f797be39!J48)+ISNUMBER('15370cab949a'!J48),"") | ... R35: =IF(ISNUMBER('827d4ae889e4'!N48)+ISNUMBER(bfe5f797be39!N48)+ISNUMBER('15370cab949a'!N48),ISNUMBER('827d4ae889e4'!N48)+ISNUMBER(bfe5f797be39!N48)+ISNUMBER('15370cab949a'!N48),"")
F36: =F20 -> Community smart infrastru… | G36: =IF(ISNUMBER('827d4ae889e4'!C49)+ISNUMBER(bfe5f797be39!C49)+ISNUMBER('15370cab949a'!C49),ISNUMBER('827d4ae889e4'!C49)+ISNUMBER(bfe5f797be39!C49)+ISNUMBER('15370cab949a'!C49),"") | H36: =IF(ISNUMBER('827d4ae889e4'!D49)+ISNUMBER(bfe5f797be39!D49)+ISNUMBER('15370cab949a'!D49),ISNUMBER('827d4ae889e4'!D49)+ISNUMBER(bfe5f797be39!D49)+ISNUMBER('15370cab949a'!D49),"") | I36: =IF(ISNUMBER('827d4ae889e4'!E49)+ISNUMBER(bfe5f797be39!E49)+ISNUMBER('15370cab949a'!E49),ISNUMBER('827d4ae889e4'!E49)+ISNUMBER(bfe5f797be39!E49)+ISNUMBER('15370cab949a'!E49),"") | J36: =IF(ISNUMBER('827d4ae889e4'!F49)+ISNUMBER(bfe5f797be39!F49)+ISNUMBER('15370cab949a'!F49),ISNUMBER('827d4ae889e4'!F49)+ISNUMBER(bfe5f797be39!F49)+ISNUMBER('15370cab949a'!F49),"") | K36: =IF(ISNUMBER('827d4ae889e4'!G49)+ISNUMBER(bfe5f797be39!G49)+ISNUMBER('15370cab949a'!G49),ISNUMBER('827d4ae889e4'!G49)+ISNUMBER(bfe5f797be39!G49)+ISNUMBER('15370cab949a'!G49),"") | L36: =IF(ISNUMBER('827d4ae889e4'!H49)+ISNUMBER(bfe5f797be39!H49)+ISNUMBER('15370cab949a'!H49),ISNUMBER('827d4ae889e4'!H49)+ISNUMBER(bfe5f797be39!H49)+ISNUMBER('15370cab949a'!H49),"") -> 1 | M36: =IF(ISNUMBER('827d4ae889e4'!I49)+ISNUMBER(bfe5f797be39!I49)+ISNUMBER('15370cab949a'!I49),ISNUMBER('827d4ae889e4'!I49)+ISNUMBER(bfe5f797be39!I49)+ISNUMBER('15370cab949a'!I49),"") | N36: =IF(ISNUMBER('827d4ae889e4'!J49)+ISNUMBER(bfe5f797be39!J49)+ISNUMBER('15370cab949a'!J49),ISNUMBER('827d4ae889e4'!J49)+ISNUMBER(bfe5f797be39!J49)+ISNUMBER('15370cab949a'!J49),"") | ... R36: =IF(ISNUMBER('827d4ae889e4'!N49)+ISNUMBER(bfe5f797be39!N49)+ISNUMBER('15370cab949a'!N49),ISNUMBER('827d4ae889e4'!N49)+ISNUMBER(bfe5f797be39!N49)+ISNUMBER('15370cab949a'!N49),"")
F37: =F21 -> Mobility… | G37: =IF(ISNUMBER('827d4ae889e4'!C50)+ISNUMBER(bfe5f797be39!C50)+ISNUMBER('15370cab949a'!C50),ISNUMBER('827d4ae889e4'!C50)+ISNUMBER(bfe5f797be39!C50)+ISNUMBER('15370cab949a'!C50),"") | H37: =IF(ISNUMBER('827d4ae889e4'!D50)+ISNUMBER(bfe5f797be39!D50)+ISNUMBER('15370cab949a'!D50),ISNUMBER('827d4ae889e4'!D50)+ISNUMBER(bfe5f797be39!D50)+ISNUMBER('15370cab949a'!D50),"") | I37: =IF(ISNUMBER('827d4ae889e4'!E50)+ISNUMBER(bfe5f797be39!E50)+ISNUMBER('15370cab949a'!E50),ISNUMBER('827d4ae889e4'!E50)+ISNUMBER(bfe5f797be39!E50)+ISNUMBER('15370cab949a'!E50),"") | J37: =IF(ISNUMBER('827d4ae889e4'!F50)+ISNUMBER(bfe5f797be39!F50)+ISNUMBER('15370cab949a'!F50),ISNUMBER('827d4ae889e4'!F50)+ISNUMBER(bfe5f797be39!F50)+ISNUMBER('15370cab949a'!F50),"") | K37: =IF(ISNUMBER('827d4ae889e4'!G50)+ISNUMBER(bfe5f797be39!G50)+ISNUMBER('15370cab949a'!G50),ISNUMBER('827d4ae889e4'!G50)+ISNUMBER(bfe5f797be39!G50)+ISNUMBER('15370cab949a'!G50),"") | L37: =IF(ISNUMBER('827d4ae889e4'!H50)+ISNUMBER(bfe5f797be39!H50)+ISNUMBER('15370cab949a'!H50),ISNUMBER('827d4ae889e4'!H50)+ISNUMBER(bfe5f797be39!H50)+ISNUMBER('15370cab949a'!H50),"") | M37: =IF(ISNUMBER('827d4ae889e4'!I50)+ISNUMBER(bfe5f797be39!I50)+ISNUMBER('15370cab949a'!I50),ISNUMBER('827d4ae889e4'!I50)+ISNUMBER(bfe5f797be39!I50)+ISNUMBER('15370cab949a'!I50),"") | N37: =IF(ISNUMBER('827d4ae889e4'!J50)+ISNUMBER(bfe5f797be39!J50)+ISNUMBER('15370cab949a'!J50),ISNUMBER('827d4ae889e4'!J50)+ISNUMBER(bfe5f797be39!J50)+ISNUMBER('15370cab949a'!J50),"") | ... R37: =IF(ISNUMBER('827d4ae889e4'!N50)+ISNUMBER(bfe5f797be39!N50)+ISNUMBER('15370cab949a'!N50),ISNUMBER('827d4ae889e4'!N50)+ISNUMBER(bfe5f797be39!N50)+ISNUMBER('15370cab949a'!N50),"")

Sheet HowTo
C1: How to use
B3: Step | C3: Description
B4: Step 1 | C4: Author/user sends their text for review (use cases, visions, ….)
B5: Step 2 | C5: LJ processes the text and..
B6: Step3 | C6: A draft assessment is created, in an excel format, and sent back o the author
C7: The authors checks green tabs, and can edit cells in yellow such as this cell. Other cells should not be edited.
B8: Step 4 | C8: Author sends back edited excel.
B9: Step 5 | C9: LJ updates the data and generates the assessment report.
B10: Step 6 | C10: Author receives an updated assessment
B12: Tabs | C12: Content
B13: Green tabs | C13: Contains assessments
B14: Blue tab | C14: Contains definition
B15: Black tab | C15: Cover hsset
B16: Orange tab | C16: How to and explanations

Sheet Definitions
A1: Definitions
B2: As per https://www.iso.org/obp/ui/en/#iso:std:iso:37104:ed-1:v1:en
A3: Purpose of sustainability
B4: Attractiveness | C4: Including: potential for economic development; general appeal to citizens and investors; richness of culture, encouragement of creativity and innovation; established connectivity and the continual development of alternative forms of mobility (such as quality of sustainable public transport infrastructures).
B5: Preservation and improvement of environment | C5: Including: climate change mitigation (such as by reducing greenhouse gas emissions; preservation, restoration and enhancement of biological diversity and ecosystem services); protection of ecosystems, (including plant and animal diversity and migration as well as genetic diversity); reducing pollution (including improving air quality and reducing health hazard).
B6: Resilience | C6: Including: preparation for climate change adaptation; climate risk reduction actions and crisis management plans, vulnerability assessment, development of social capital and capability, demographic evolution; financial and economic shocks and stresses testing and organisational preparedness.
B7: Responsible resource use | C7: Including: improved land use management; reducing, reusing and recycling of materials; respect for scarcity of all types of resources (notably water and energy). Promoting the environmentally safe reuse and recycling/treatment of e-waste and batteries. Encouraging preparation for reuse of products, and imposing conditions for the safe recycling, recovery and disposal of waste materials.
B8: Social cohesion | C8: Including: Equitable accessibility to services; dialogue with external parties not limited by city boundaries, enhancing and celebrating diversity; heritage and building a sense of identity; inclusiveness; mutuality, and shared experiences; rootedness; sense of belonging and increasing opportunities for social mobility, cohesion and the reduction of inequalities. Social cohesion is a relevant element of Agenda 2030 which focuses on reaching the SDGs. It is summed up by the phrase "Leave no one behind"a.
B9: Well-being | C9: Including: access to quality-of-life opportunities; all-life education and job-related training, human capital improvement; healthy environment and liveable city; security; building self-confidence and collective maturity.
A11: Sustainability issue
B12: Governance, empowerment and engagement | C12: Including: actions aimed at involving the different local actors and encouraging them to work together on collaborative projects. Such actors might include public actors, private actors, universities and research, associations, charities and citizens.
B13: Education and capacity building | C13: Including: actions aimed at raising awareness, providing information, communication, education and training for different audiences and levels.
B14: Innovation, creativity and research | C14: Including: actions involving innovation, creativity and research. For example, the establishment of innovation clusters, places of physical and virtual exchanges, the definition of public policies to support the realization of innovative demonstrators in the territory. NOTE Innovation can take many forms, including social, technological, organizational, economic and financial innovations.
B15: Health and care in the community | C15: Including: actions aimed at improving health and care in the community, with a particular emphasis on projects targeting the most vulnerable and fragile sections of the population (e.g. children, the elderly, people with disabilities, and people who are insecure, mentally ill or distressed) and also projects targeting areas that lack access to care and health facilities.
B16: Culture and community identity | C16: Including: actions aimed at supporting and promoting culture in its diversity, notably minority and marginalised cultures. It also concerns actions aimed at fostering meeting opportunities and exchanges between different cultures both inside and outside the territory.
B17: Living together, interdependence and mutuality | C17: Including: actions and mechanisms aimed at promoting equal treatment of all citizens. It also concerns actions that encourage living together, constructive challenge and policies reducing inequality in all its forms.
B18: Economy and sustainable production and consumption | C18: Including: actions aimed at promoting and fostering the development of sustainable production and consumption, for example by establishing rules governing public procurement.
B19: Living and working environment | C19: Including: actions in the field of construction or renovation of buildings and public spaces. Actions aimed at encouraging good appropriation of buildings and public space by different users (e.g. adaptability, flexibility and innovation).
B20: Safety and security | C20: Including: actions aimed at preventing and managing all types of risks, actions aimed at reducing the causes of delinquency and crime; actions to ensure general safety and security.
B21: Biodiversity and ecosystem services | C21: Including: actions aimed at protecting, integrating and promoting natural environments in the city and its surroundings, for example green spaces, landscapes, wetlands and aquatic environments, ecological corridors, fauna and flora. Actions aimed at better understanding and using the positive impact of diverse ecosystems.
B22: Community smart infrastructures | C22: Including: actions aimed at ensuring high-quality utilities, for example urban water supply services and wastewater treatment; collection and treatment of waste; production, transmission and distribution of energy (e.g. electricity, heat, cold); integration of internet and other communication services.
B23: Mobility | C23: Including: actions aimed at promoting the development of public transport, and of active and alternative transportation modes (e.g. electric cars, carpools). It includes actions aimed at fostering the integration of information technology in the management of mobility, the regulation of goods and people transportation (e.g. reduction of speed) and parking policy.

Sheet 827d4ae889e4
B2: Self assessment sheet
B4: Activity | C4: Review of D7.2
B5: Title | C5: Aarhus Living Lab's sustainable initiatives. | J5: ID: | L5: 827d4ae889e4
B6: Deliverable | C6: D7.2 | J6: LL: | L6: Aarhus
B7: Reviewed by | J7: Date of review:
B8: Review | C8: Aarhus University's Living Lab (LL) is paving the way towards a sustainable future with its groundbreaking initiatives! The LL's overall purpose is to curate new research and apply evidence-based holistic action research, focusing on social sustainability concepts in real construction projects ultimately for contributing to the development of a modern sustainable city integrated Campus, known as Campus 2.0. The Living Lab (LL) encompasses a diverse range of areas, including technological, social, natural, and physical aspects, all of which play crucial roles in the creation of a Green Building Neighbourhood (GBN). Here's how the LL is making a difference across various aspects: Technological: The LL is at the forefront of developing and testing cutting-edge technologies and tools. We are working on an enhanced decision-support tool for architects and engineers, to facilitate better decision-making in the early phases of construction projects. Social: Making the intangible social sustainability tangible and quantifiable is the LL's aim. We are creating social sustainability subcategories and generating valuable knowledge and experience that can be applied in real-world projects, fostering a more inclusive and sustainable society. Natural: The LL is committed to achieving net-zero environmental sustainability. We are promoting functional architecture, testing and prototyping green deal transitional examples, and aiming for DGNB gold certifications for their sustainability goals. Physical: Through the LL's efforts, the campus district is undergoing a remarkable physical transformation. We are deeply refurbishing existing buildings, adding new ones, and ensuring architectural and structural features are preserved while meeting the needs of the university and its users. Looking ahead, the vision for the Aarhus Living Lab and Aarhus University's Campus 2.0 is to "Make the intangible qualities, tangible." We aspire to translate social sustainability concepts into concrete, measurable outcomes. By integrating our findings, the LL will contribute to a modern, sustainable, and vibrant University City connected to the University Park.
B10: ID | C10: Purp. | D10: Act. | E10: Bld. | F10: Neig. | G10: Justification
C11: A1 | D11: B3 | E11: 5 | G11: The text highlights the groundbreaking initiatives and cutting-edge technologies developed and tested at the Living Lab, emphasizing the innovative and creative research and development work being carried out.
C12: A3 | D12: B10 | F12: 4 | G12: The Living Lab is committed to achieving net-zero environmental sustainability, promoting functional architecture, and testing green deal transitional examples, which contribute to the preservation and enhancement of biodiversity and ecosystem services within the campus district.
C13: A4 | D13: B8 | F13: 3 | G13: The text mentions the refurbishment of existing buildings, the addition of new ones, and ensuring architectural and structural features are preserved, indicating responsible resource use in the living and working environment of the campus district.
C14: A5 | D14: B2 | E14: 3 | G14: The Living Lab aims to make the intangible social sustainability tangible and quantifiable, creating social sustainability subcategories and generating valuable knowledge and experience applied in real-world projects, fostering a more inclusive and sustainable society. This aligns with education and capacity building at the building scale.
C15: A6 | D15: B4 | F15: 4 | G15: The vision for the Aarhus Living Lab and Aarhus University's Campus 2.0 is to make the intangible qualities tangible, translating social sustainability concepts into concrete, measurable outcomes, which directly impacts the well-being of the community within the campus district.
C16: A1 | D16: B3 | E16: 5 | G16: The text highlights the groundbreaking initiatives and cutting-edge technologies being developed and tested at the Living Lab, emphasizing the focus on innovation and research in the context of sustainability and development of Campus 2.0.
C17: A2 | D17: B10 | E17: 4 | G17: The Living Lab's commitment to achieving net-zero environmental sustainability, testing and prototyping green deal transitional examples, and aiming for DGNB gold certifications demonstrates a strong emphasis on protecting and promoting natural environments within the Campus 2.0 development.
C18: A4 | D18: B8 | E18: 3 | G18: The efforts to deeply refurbish existing buildings, add new ones, and ensure architectural and structural features are preserved while meeting the needs of the university and its users indicate a focus on responsible resource use in the context of living and working environments.
C19: A5 | D19: B5 | E19: 4 | G19: The text emphasizes the aim of creating social sustainability subcategories, fostering a more inclusive and sustainable society, and translating social sustainability concepts into concrete, measurable outcomes, aligning with the promotion of culture and community identity within the university city and Campus 2.0.
B22: Definitions | C22: A (Purposes) | I22: B (Actions)
C23: 1. Attractiveness | I23: 1. Governance, empowerment, and engagement
C24: 2. Preservation and improvement of the environment | I24: 2. Education and capacity building
C25: 3. Resilience | I25: 3. Innovation, creativity, and research
C26: 4. Responsible resource use | I26: 4. Health and care in the community
C27: 5. Social cohesion | I27: 5. Culture and community identity
C28: 6. Wellbeing | I28: 6. Living together, interdependence and mutuality
I29: 7. Economy and sustainable production and consumption
I30: 8. Living and working environment
I31: 9. Safety and security
I32: 10. Biodiversity and ecosystem services
I33: 11. Community smart infrastructures
I34: 12. Mobility
C37: A1 | E37: A2 | G37: A3 | I37: A4 | K37: A5 | M37: A6
C38: Bld. | D38: Neig. | E38: Bld. | F38: Neig. | G38: Bld. | H38: Neig. | I38: Bld. | J38: Neig. | K38: Bld. | L38: Neig. | M38: Bld. | N38: Neig.
B39: B1 | C39: =IFERROR(AVERAGEIFS($E$11:$E$20,$C$11:$C$20,C$37,$D$11:$D$20,$B39),"") | D39: =IFERROR(AVERAGEIFS($F$11:$F$20,$C$11:$C$20,C$37,$D$11:$D$20,$B39),"") | E39: =IFERROR(AVERAGEIFS($E$11:$E$20,$C$11:$C$20,E$37,$D$11:$D$20,$B39),"") | F39: =IFERROR(AVERAGEIFS($F$11:$F$20,$C$11:$C$20,E$37,$D$11:$D$20,$B39),"") | G39: =IFERROR(AVERAGEIFS($E$11:$E$20,$C$11:$C$20,G$37,$D$11:$D$20,$B39),"") | H39: =IFERROR(AVERAGEIFS($F$11:$F$20,$C$11:$C$20,G$37,$D$11:$D$20,$B39),"") | I39: =IFERROR(AVERAGEIFS($E$11:$E$20,$C$11:$C$20,I$37,$D$11:$D$20,$B39),"") | J39: =IFERROR(AVERAGEIFS($F$11:$F$20,$C$11:$C$20,I$37,$D$11:$D$20,$B39),"") | K39: =IFERROR(AVERAGEIFS($E$11:$E$20,$C$11:$C$20,K$37,$D$11:$D$20,$B39),"") | L39: =IFERROR(AVERAGEIFS($F$11:$F$20,$C$11:$C$20,K$37,$D$11:$D$20,$B39),"") | M39: =IFERROR(AVERAGEIFS($E$11:$E$20,$C$11:$C$20,M$37,$D$11:$D$20,$B39),"") | N39: =IFERROR(AVERAGEIFS($F$11:$F$20,$C$11:$C$20,M$37,$D$11:$D$20,$B39),"")
B40: B2 | C40: =IFERROR(AVERAGEIFS($E$11:$E$20,$C$11:$C$20,C$37,$D$11:$D$20,$B40),"") | D40: =IFERROR(AVERAGEIFS($F$11:$F$20,$C$11:$C$20,C$37,$D$11:$D$20,$B40),"") | E40: =IFERROR(AVERAGEIFS($E$11:$E$20,$C$11:$C$20,E$37,$D$11:$D$20,$B40),"") | F40: =IFERROR(AVERAGEIFS($F$11:$F$20,$C$11:$C$20,E$37,$D$11:$D$20,$B40),"") | G40: =IFERROR(AVERAGEIFS($E$11:$E$20,$C$11:$C$20,G$37,$D$11:$D$20,$B40),"") | H40: =IFERROR(AVERAGEIFS($F$11:$F$20,$C$11:$C$20,G$37,$D$11:$D$20,$B40),"") | I40: =IFERROR(AVERAGEIFS($E$11:$E$20,$C$11:$C$20,I$37,$D$11:$D$20,$B40),"") | J40: =IFERROR(AVERAGEIFS($F$11:$F$20,$C$11:$C$20,I$37,$D$11:$D$20,$B40),"") | K40: =IFERROR(AVERAGEIFS($E$11:$E$20,$C$11:$C$20,K$37,$D$11:$D$20,$B40),"") -> 3 | L40: =IFERROR(AVERAGEIFS($F$11:$F$20,$C$11:$C$20,K$37,$D$11:$D$20,$B40),"") | M40: =IFERROR(AVERAGEIFS($E$11:$E$20,$C$11:$C$20,M$37,$D$11:$D$20,$B40),"") | N40: =IFERROR(AVERAGEIFS($F$11:$F$20,$C$11:$C$20,M$37,$D$11:$D$20,$B40),"")
B41: B3 | C41: =IFERROR(AVERAGEIFS($E$11:$E$20,$C$11:$C$20,C$37,$D$11:$D$20,$B41),"") -> 5 | D41: =IFERROR(AVERAGEIFS($F$11:$F$20,$C$11:$C$20,C$37,$D$11:$D$20,$B41),"") | E41: =IFERROR(AVERAGEIFS($E$11:$E$20,$C$11:$C$20,E$37,$D$11:$D$20,$B41),"") | F41: =IFERROR(AVERAGEIFS($F$11:$F$20,$C$11:$C$20,E$37,$D$11:$D$20,$B41),"") | G41: =IFERROR(AVERAGEIFS($E$11:$E$20,$C$11:$C$20,G$37,$D$11:$D$20,$B41),"") | H41: =IFERROR(AVERAGEIFS($F$11:$F$20,$C$11:$C$20,G$37,$D$11:$D$20,$B41),"") | I41: =IFERROR(AVERAGEIFS($E$11:$E$20,$C$11:$C$20,I$37,$D$11:$D$20,$B41),"") | J41: =IFERROR(AVERAGEIFS($F$11:$F$20,$C$11:$C$20,I$37,$D$11:$D$20,$B41),"") | K41: =IFERROR(AVERAGEIFS($E$11:$E$20,$C$11:$C$20,K$37,$D$11:$D$20,$B41),"") | L41: =IFERROR(AVERAGEIFS($F$11:$F$20,$C$11:$C$20,K$37,$D$11:$D$20,$B41),"") | M41: =IFERROR(AVERAGEIFS($E$11:$E$20,$C$11:$C$20,M$37,$D$11:$D$20,$B41),"") | N41: =IFERROR(AVERAGEIFS($F$11:$F$20,$C$11:$C$20,M$37,$D$11:$D$20,$B41),"")
B42: B4 | C42: =IFERROR(AVERAGEIFS($E$11:$E$20,$C$11:$C$20,C$37,$D$11:$D$20,$B42),"") | D42: =IFERROR(AVERAGEIFS($F$11:$F$20,$C$11:$C$20,C$37,$D$11:$D$20,$B42),"") | E42: =IFERROR(AVERAGEIFS($E$11:$E$20,$C$11:$C$20,E$37,$D$11:$D$20,$B42),"") | F42: =IFERROR(AVERAGEIFS($F$11:$F$20,$C$11:$C$20,E$37,$D$11:$D$20,$B42),"") | G42: =IFERROR(AVERAGEIFS($E$11:$E$20,$C$11:$C$20,G$37,$D$11:$D$20,$B42),"") | H42: =IFERROR(AVERAGEIFS($F$11:$F$20,$C$11:$C$20,G$37,$D$11:$D$20,$B42),"") | I42: =IFERROR(AVERAGEIFS($E$11:$E$20,$C$11:$C$20,I$37,$D$11:$D$20,$B42),"") | J42: =IFERROR(AVERAGEIFS($F$11:$F$20,$C$11:$C$20,I$37,$D$11:$D$20,$B42),"") | K42: =IFERROR(AVERAGEIFS($E$11:$E$20,$C$11:$C$20,K$37,$D$11:$D$20,$B42),"") | L42: =IFERROR(AVERAGEIFS($F$11:$F$20,$C$11:$C$20,K$37,$D$11:$D$20,$B42),"") | M42: =IFERROR(AVERAGEIFS($E$11:$E$20,$C$11:$C$20,M$37,$D$11:$D$20,$B42),"") | N42: =IFERROR(AVERAGEIFS($F$11:$F$20,$C$11:$C$20,M$37,$D$11:$D$20,$B42),"") -> 4
B43: B5 | C43: =IFERROR(AVERAGEIFS($E$11:$E$20,$C$11:$C$20,C$37,$D$11:$D$20,$B43),"") | D43: =IFERROR(AVERAGEIFS($F$11:$F$20,$C$11:$C$20,C$37,$D$11:$D$20,$B43),"") | E43: =IFERROR(AVERAGEIFS($E$11:$E$20,$C$11:$C$20,E$37,$D$11:$D$20,$B43),"") | F43: =IFERROR(AVERAGEIFS($F$11:$F$20,$C$11:$C$20,E$37,$D$11:$D$20,$B43),"") | G43: =IFERROR(AVERAGEIFS($E$11:$E$20,$C$11:$C$20,G$37,$D$11:$D$20,$B43),"") | H43: =IFERROR(AVERAGEIFS($F$11:$F$20,$C$11:$C$20,G$37,$D$11:$D$20,$B43),"") | I43: =IFERROR(AVERAGEIFS($E$11:$E$20,$C$11:$C$20,I$37,$D$11:$D$20,$B43),"") | J43: =IFERROR(AVERAGEIFS($F$11:$F$20,$C$11:$C$20,I$37,$D$11:$D$20,$B43),"") | K43: =IFERROR(AVERAGEIFS($E$11:$E$20,$C$11:$C$20,K$37,$D$11:$D$20,$B43),"") -> 4 | L43: =IFERROR(AVERAGEIFS($F$11:$F$20,$C$11:$C$20,K$37,$D$11:$D$20,$B43),"") | M43: =IFERROR(AVERAGEIFS($E$11:$E$20,$C$11:$C$20,M$37,$D$11:$D$20,$B43),"") | N43: =IFERROR(AVERAGEIFS($F$11:$F$20,$C$11:$C$20,M$37,$D$11:$D$20,$B43),"")
B44: B6 | C44: =IFERROR(AVERAGEIFS($E$11:$E$20,$C$11:$C$20,C$37,$D$11:$D$20,$B44),"") | D44: =IFERROR(AVERAGEIFS($F$11:$F$20,$C$11:$C$20,C$37,$D$11:$D$20,$B44),"") | E44: =IFERROR(AVERAGEIFS($E$11:$E$20,$C$11:$C$20,E$37,$D$11:$D$20,$B44),"") | F44: =IFERROR(AVERAGEIFS($F$11:$F$20,$C$11:$C$20,E$37,$D$11:$D$20,$B44),"") | G44: =IFERROR(AVERAGEIFS($E$11:$E$20,$C$11:$C$20,G$37,$D$11:$D$20,$B44),"") | H44: =IFERROR(AVERAGEIFS($F$11:$F$20,$C$11:$C$20,G$37,$D$11:$D$20,$B44),"") | I44: =IFERROR(AVERAGEIFS($E$11:$E$20,$C$11:$C$20,I$37,$D$11:$D$20,$B44),"") | J44: =IFERROR(AVERAGEIFS($F$11:$F$20,$C$11:$C$20,I$37,$D$11:$D$20,$B44),"") | K44: =IFERROR(AVERAGEIFS($E$11:$E$20,$C$11:$C$20,K$37,$D$11:$D$20,$B44),"") | L44: =IFERROR(AVERAGEIFS($F$11:$F$20,$C$11:$C$20,K$37,$D$11:$D$20,$B44),"") | M44: =IFERROR(AVERAGEIFS($E$11:$E$20,$C$11:$C$20,M$37,$D$11:$D$20,$B44),"") | N44: =IFERROR(AVERAGEIFS($F$11:$F$20,$C$11:$C$20,M$37,$D$11:$D$20,$B44),"")
B45: B7 | C45: =IFERROR(AVERAGEIFS($E$11:$E$20,$C$11:$C$20,C$37,$D$11:$D$20,$B45),"") | D45: =IFERROR(AVERAGEIFS($F$11:$F$20,$C$11:$C$20,C$37,$D$11:$D$20,$B45),"") | E45: =IFERROR(AVERAGEIFS($E$11:$E$20,$C$11:$C$20,E$37,$D$11:$D$20,$B45),"") | F45: =IFERROR(AVERAGEIFS($F$11:$F$20,$C$11:$C$20,E$37,$D$11:$D$20,$B45),"") | G45: =IFERROR(AVERAGEIFS($E$11:$E$20,$C$11:$C$20,G$37,$D$11:$D$20,$B45),"") | H45: =IFERROR(AVERAGEIFS($F$11:$F$20,$C$11:$C$20,G$37,$D$11:$D$20,$B45),"") | I45: =IFERROR(AVERAGEIFS($E$11:$E$20,$C$11:$C$20,I$37,$D$11:$D$20,$B45),"") | J45: =IFERROR(AVERAGEIFS($F$11:$F$20,$C$11:$C$20,I$37,$D$11:$D$20,$B45),"") | K45: =IFERROR(AVERAGEIFS($E$11:$E$20,$C$11:$C$20,K$37,$D$11:$D$20,$B45),"") | L45: =IFERROR(AVERAGEIFS($F$11:$F$20,$C$11:$C$20,K$37,$D$11:$D$20,$B45),"") | M45: =IFERROR(AVERAGEIFS($E$11:$E$20,$C$11:$C$20,M$37,$D$11:$D$20,$B45),"") | N45: =IFERROR(AVERAGEIFS($F$11:$F$20,$C$11:$C$20,M$37,$D$11:$D$20,$B45),"")
B46: B8 | C46: =IFERROR(AVERAGEIFS($E$11:$E$20,$C$11:$C$20,C$37,$D$11:$D$20,$B46),"") | D46: =IFERROR(AVERAGEIFS($F$11:$F$20,$C$11:$C$20,C$37,$D$11:$D$20,$B46),"") | E46: =IFERROR(AVERAGEIFS($E$11:$E$20,$C$11:$C$20,E$37,$D$11:$D$20,$B46),"") | F46: =IFERROR(AVERAGEIFS($F$11:$F$20,$C$11:$C$20,E$37,$D$11:$D$20,$B46),"") | G46: =IFERROR(AVERAGEIFS($E$11:$E$20,$C$11:$C$20,G$37,$D$11:$D$20,$B46),"") | H46: =IFERROR(AVERAGEIFS($F$11:$F$20,$C$11:$C$20,G$37,$D$11:$D$20,$B46),"") | I46: =IFERROR(AVERAGEIFS($E$11:$E$20,$C$11:$C$20,I$37,$D$11:$D$20,$B46),"") -> 3 | J46: =IFERROR(AVERAGEIFS($F$11:$F$20,$C$11:$C$20,I$37,$D$11:$D$20,$B46),"") -> 3 | K46: =IFERROR(AVERAGEIFS($E$11:$E$20,$C$11:$C$20,K$37,$D$11:$D$20,$B46),"") | L46: =IFERROR(AVERAGEIFS($F$11:$F$20,$C$11:$C$20,K$37,$D$11:$D$20,$B46),"") | M46: =IFERROR(AVERAGEIFS($E$11:$E$20,$C$11:$C$20,M$37,$D$11:$D$20,$B46),"") | N46: =IFERROR(AVERAGEIFS($F$11:$F$20,$C$11:$C$20,M$37,$D$11:$D$20,$B46),"")
B47: B9 | C47: =IFERROR(AVERAGEIFS($E$11:$E$20,$C$11:$C$20,C$37,$D$11:$D$20,$B47),"") | D47: =IFERROR(AVERAGEIFS($F$11:$F$20,$C$11:$C$20,C$37,$D$11:$D$20,$B47),"") | E47: =IFERROR(AVERAGEIFS($E$11:$E$20,$C$11:$C$20,E$37,$D$11:$D$20,$B47),"") | F47: =IFERROR(AVERAGEIFS($F$11:$F$20,$C$11:$C$20,E$37,$D$11:$D$20,$B47),"") | G47: =IFERROR(AVERAGEIFS($E$11:$E$20,$C$11:$C$20,G$37,$D$11:$D$20,$B47),"") | H47: =IFERROR(AVERAGEIFS($F$11:$F$20,$C$11:$C$20,G$37,$D$11:$D$20,$B47),"") | I47: =IFERROR(AVERAGEIFS($E$11:$E$20,$C$11:$C$20,I$37,$D$11:$D$20,$B47),"") | J47: =IFERROR(AVERAGEIFS($F$11:$F$20,$C$11:$C$20,I$37,$D$11:$D$20,$B47),"") | K47: =IFERROR(AVERAGEIFS($E$11:$E$20,$C$11:$C$20,K$37,$D$11:$D$20,$B47),"") | L47: =IFERROR(AVERAGEIFS($F$11:$F$20,$C$11:$C$20,K$37,$D$11:$D$20,$B47),"") | M47: =IFERROR(AVERAGEIFS($E$11:$E$20,$C$11:$C$20,M$37,$D$11:$D$20,$B47),"") | N47: =IFERROR(AVERAGEIFS($F$11:$F$20,$C$11:$C$20,M$37,$D$11:$D$20,$B47),"")
...

Sheet bfe5f797be39
B2: Self assessment sheet
B4: Activity | C4: Review of D7.2
B5: Title | C5: Aarhus University's Living Lab mission: sustainability. | J5: ID: | L5: bfe5f797be39
B6: Deliverable | C6: D7.2 | J6: LL: | L6: Aarhus
B7: Reviewed by | J7: Date of review:
B8: Review | C8: Aarhus University's Living Lab (LL) is paving the way towards a sustainable future with its groundbreaking initiatives! The LL's overall purpose is to curate new research and apply evidence-based holistic action research, focusing on social sustainability concepts in real construction projects ultimately for contributing to the development of a modern sustainable city integrated Campus, known as Campus 2.0. The Living Lab (LL) encompasses a diverse range of areas, including technological, social, natural, and physical aspects, all of which play crucial roles in the creation of a Green Building Neighbourhood (GBN). Here's how the LL is making a difference across various aspects: Technological: The LL is at the forefront of developing and testing cutting-edge technologies and tools. We are working on an enhanced decision-support tool for architects and engineers, to facilitate better decision-making in the early phases of construction projects. Social: Making the intangible social sustainability tangible and quantifiable is the LL's aim. We are creating social sustainability subcategories and generating valuable knowledge and experience that can be applied in real-world projects, fostering a more inclusive and sustainable society. Natural: The LL is committed to achieving net-zero environmental sustainability. We are promoting functional architecture, testing and prototyping green deal transitional examples, and aiming for DGNB gold certifications for their sustainability goals. Physical: Through the LL's efforts, the campus district is undergoing a remarkable physical transformation. We are deeply refurbishing existing buildings, adding new ones, and ensuring architectural and structural features are preserved while meeting the needs of the university and its users. Looking ahead, the vision for the Aarhus Living Lab and Aarhus University's Campus 2.0 is to "Make the intangible qualities, tangible." We aspire to translate social sustainability concepts into concrete, measurable outcomes. By integrating our findings, the LL will contribute to a modern, sustainable, and vibrant University City connected to the University Park..
B10: ID | C10: Purp. | D10: Act. | E10: Bld. | F10: Neig. | G10: Justification
C11: A1 | D11: B3 | E11: 5 | G11: The text emphasizes groundbreaking initiatives and the development of new research, indicating a focus on innovation, creativity, and research in the context of the Living Lab's activities.
C12: A4 | D12: B10 | E12: 4 | G12: The Living Lab is committed to achieving net-zero environmental sustainability and promoting functional architecture, which aligns with responsible resource use and the protection and enhancement of biodiversity and ecosystem services.
C13: A6 | D13: B8 | E13: 4 | G13: The text discusses the physical transformation of the campus district and the refurbishment of existing buildings, which indicates a focus on creating a healthy and conducive living and working environment for the university and its users.
C14: A3 | D14: B11 | F14: 4 | G14: The vision for the Living Lab and Aarhus University's Campus 2.0 includes the integration of findings to contribute to a modern, sustainable, and vibrant University City connected to the University Park, indicating a focus on building smart infrastructures and enhancing resilience at the neighborhood scale.
C15: A5 | D15: B5 | E15: 3 | G15: The text highlights the aim of making intangible social sustainability tangible and quantifiable, fostering a more inclusive and sustainable society, which relates to the promotion of culture and community identity and the enhancement of social cohesion within the university community.
B22: Definitions | C22: A (Purposes) | I22: B (Actions)
C23: 1. Attractiveness | I23: 1. Governance, empowerment, and engagement
C24: 2. Preservation and improvement of the environment | I24: 2. Education and capacity building
C25: 3. Resilience | I25: 3. Innovation, creativity, and research
C26: 4. Responsible resource use | I26: 4. Health and care in the community
C27: 5. Social cohesion | I27: 5. Culture and community identity
C28: 6. Wellbeing | I28: 6. Living together, interdependence and mutuality
I29: 7. Economy and sustainable production and consumption
I30: 8. Living and working environment
I31: 9. Safety and security
I32: 10. Biodiversity and ecosystem services
I33: 11. Community smart infrastructures
I34: 12. Mobility
C37: A1 | E37: A2 | G37: A3 | I37: A4 | K37: A5 | M37: A6
C38: Bld. | D38: Neig. | E38: Bld. | F38: Neig. | G38: Bld. | H38: Neig. | I38: Bld. | J38: Neig. | K38: Bld. | L38: Neig. | M38: Bld. | N38: Neig.
B39: B1 | C39: =IFERROR(AVERAGEIFS($E$11:$E$20,$C$11:$C$20,C$37,$D$11:$D$20,$B39),"") | D39: =IFERROR(AVERAGEIFS($F$11:$F$20,$C$11:$C$20,C$37,$D$11:$D$20,$B39),"") | E39: =IFERROR(AVERAGEIFS($E$11:$E$20,$C$11:$C$20,E$37,$D$11:$D$20,$B39),"") | F39: =IFERROR(AVERAGEIFS($F$11:$F$20,$C$11:$C$20,E$37,$D$11:$D$20,$B39),"") | G39: =IFERROR(AVERAGEIFS($E$11:$E$20,$C$11:$C$20,G$37,$D$11:$D$20,$B39),"") | H39: =IFERROR(AVERAGEIFS($F$11:$F$20,$C$11:$C$20,G$37,$D$11:$D$20,$B39),"") | I39: =IFERROR(AVERAGEIFS($E$11:$E$20,$C$11:$C$20,I$37,$D$11:$D$20,$B39),"") | J39: =IFERROR(AVERAGEIFS($F$11:$F$20,$C$11:$C$20,I$37,$D$11:$D$20,$B39),"") | K39: =IFERROR(AVERAGEIFS($E$11:$E$20,$C$11:$C$20,K$37,$D$11:$D$20,$B39),"") | L39: =IFERROR(AVERAGEIFS($F$11:$F$20,$C$11:$C$20,K$37,$D$11:$D$20,$B39),"") | M39: =IFERROR(AVERAGEIFS($E$11:$E$20,$C$11:$C$20,M$37,$D$11:$D$20,$B39),"") | N39: =IFERROR(AVERAGEIFS($F$11:$F$20,$C$11:$C$20,M$37,$D$11:$D$20,$B39),"")
